Workbook

Sheet Consolidado
A1: Nombre jugador | B1: Posiciones | C1: Ritmo base | D1: Ataque | E1: Solidez | F1: Tecnica | G1: Ritmo | H1: Equipo | I1: Mentalidad | J1: Regularidad | K1: Arquero | L1: Comentarios
A2: ALE CUERVO | B2: LAT/MED | C2: lento | D2: =IFERROR(AVERAGE('Directivo 1'!D2,'Directivo 2'!D2,'Directivo 3'!D2,'Directivo 4'!D2,'Directivo 5'!D2),"") | E2: =IFERROR(AVERAGE('Directivo 1'!E2,'Directivo 2'!E2,'Directivo 3'!E2,'Directivo 4'!E2,'Directivo 5'!E2),"") | F2: =IFERROR(AVERAGE('Directivo 1'!F2,'Directivo 2'!F2,'Directivo 3'!F2,'Directivo 4'!F2,'Directivo 5'!F2),"") | G2: =IFERROR(AVERAGE('Directivo 1'!G2,'Directivo 2'!G2,'Directivo 3'!G2,'Directivo 4'!G2,'Directivo 5'!G2),"") | H2: =IFERROR(AVERAGE('Directivo 1'!H2,'Directivo 2'!H2,'Directivo 3'!H2,'Directivo 4'!H2,'Directivo 5'!H2),"") | I2: =IFERROR(AVERAGE('Directivo 1'!I2,'Directivo 2'!I2,'Directivo 3'!I2,'Directivo 4'!I2,'Directivo 5'!I2),"") | J2: =IFERROR(AVERAGE('Directivo 1'!J2,'Directivo 2'!J2,'Directivo 3'!J2,'Directivo 4'!J2,'Directivo 5'!J2),"") | K2: =IFERROR(AVERAGE('Directivo 1'!K2,'Directivo 2'!K2,'Directivo 3'!K2,'Directivo 4'!K2,'Directivo 5'!K2),"") | L2: =TEXTJOIN(" | ",TRUE,'Directivo 1'!L2,'Directivo 2'!L2,'Directivo 3'!L2,'Directivo 4'!L2,'Directivo 5'!L2)
A3: ALEXIS | B3: LAT/MED | C3: rapido | D3: =IFERROR(AVERAGE('Directivo 1'!D3,'Directivo 2'!D3,'Directivo 3'!D3,'Directivo 4'!D3,'Directivo 5'!D3),"") | E3: =IFERROR(AVERAGE('Directivo 1'!E3,'Directivo 2'!E3,'Directivo 3'!E3,'Directivo 4'!E3,'Directivo 5'!E3),"") | F3: =IFERROR(AVERAGE('Directivo 1'!F3,'Directivo 2'!F3,'Directivo 3'!F3,'Directivo 4'!F3,'Directivo 5'!F3),"") | G3: =IFERROR(AVERAGE('Directivo 1'!G3,'Directivo 2'!G3,'Directivo 3'!G3,'Directivo 4'!G3,'Directivo 5'!G3),"") | H3: =IFERROR(AVERAGE('Directivo 1'!H3,'Directivo 2'!H3,'Directivo 3'!H3,'Directivo 4'!H3,'Directivo 5'!H3),"") | I3: =IFERROR(AVERAGE('Directivo 1'!I3,'Directivo 2'!I3,'Directivo 3'!I3,'Directivo 4'!I3,'Directivo 5'!I3),"") | J3: =IFERROR(AVERAGE('Directivo 1'!J3,'Directivo 2'!J3,'Directivo 3'!J3,'Directivo 4'!J3,'Directivo 5'!J3),"") | K3: =IFERROR(AVERAGE('Directivo 1'!K3,'Directivo 2'!K3,'Directivo 3'!K3,'Directivo 4'!K3,'Directivo 5'!K3),"") | L3: =TEXTJOIN(" | ",TRUE,'Directivo 1'!L3,'Directivo 2'!L3,'Directivo 3'!L3,'Directivo 4'!L3,'Directivo 5'!L3)
A4: ANIBAL | B4: DEL | C4: lento | D4: =IFERROR(AVERAGE('Directivo 1'!D4,'Directivo 2'!D4,'Directivo 3'!D4,'Directivo 4'!D4,'Directivo 5'!D4),"") | E4: =IFERROR(AVERAGE('Directivo 1'!E4,'Directivo 2'!E4,'Directivo 3'!E4,'Directivo 4'!E4,'Directivo 5'!E4),"") | F4: =IFERROR(AVERAGE('Directivo 1'!F4,'Directivo 2'!F4,'Directivo 3'!F4,'Directivo 4'!F4,'Directivo 5'!F4),"") | G4: =IFERROR(AVERAGE('Directivo 1'!G4,'Directivo 2'!G4,'Directivo 3'!G4,'Directivo 4'!G4,'Directivo 5'!G4),"") | H4: =IFERROR(AVERAGE('Directivo 1'!H4,'Directivo 2'!H4,'Directivo 3'!H4,'Directivo 4'!H4,'Directivo 5'!H4),"") | I4: =IFERROR(AVERAGE('Directivo 1'!I4,'Directivo 2'!I4,'Directivo 3'!I4,'Directivo 4'!I4,'Directivo 5'!I4),"") | J4: =IFERROR(AVERAGE('Directivo 1'!J4,'Directivo 2'!J4,'Directivo 3'!J4,'Directivo 4'!J4,'Directivo 5'!J4),"") | K4: =IFERROR(AVERAGE('Directivo 1'!K4,'Directivo 2'!K4,'Directivo 3'!K4,'Directivo 4'!K4,'Directivo 5'!K4),"") | L4: =TEXTJOIN(" | ",TRUE,'Directivo 1'!L4,'Directivo 2'!L4,'Directivo 3'!L4,'Directivo 4'!L4,'Directivo 5'!L4)
A5: AUGUSTO | B5: MED/LAT | C5: rapido | D5: =IFERROR(AVERAGE('Directivo 1'!D5,'Directivo 2'!D5,'Directivo 3'!D5,'Directivo 4'!D5,'Directivo 5'!D5),"") | E5: =IFERROR(AVERAGE('Directivo 1'!E5,'Directivo 2'!E5,'Directivo 3'!E5,'Directivo 4'!E5,'Directivo 5'!E5),"") | F5: =IFERROR(AVERAGE('Directivo 1'!F5,'Directivo 2'!F5,'Directivo 3'!F5,'Directivo 4'!F5,'Directivo 5'!F5),"") | G5: =IFERROR(AVERAGE('Directivo 1'!G5,'Directivo 2'!G5,'Directivo 3'!G5,'Directivo 4'!G5,'Directivo 5'!G5),"") | H5: =IFERROR(AVERAGE('Directivo 1'!H5,'Directivo 2'!H5,'Directivo 3'!H5,'Directivo 4'!H5,'Directivo 5'!H5),"") | I5: =IFERROR(AVERAGE('Directivo 1'!I5,'Directivo 2'!I5,'Directivo 3'!I5,'Directivo 4'!I5,'Directivo 5'!I5),"") | J5: =IFERROR(AVERAGE('Directivo 1'!J5,'Directivo 2'!J5,'Directivo 3'!J5,'Directivo 4'!J5,'Directivo 5'!J5),"") | K5: =IFERROR(AVERAGE('Directivo 1'!K5,'Directivo 2'!K5,'Directivo 3'!K5,'Directivo 4'!K5,'Directivo 5'!K5),"") | L5: =TEXTJOIN(" | ",TRUE,'Directivo 1'!L5,'Directivo 2'!L5,'Directivo 3'!L5,'Directivo 4'!L5,'Directivo 5'!L5)
A6: BETO | B6: DEL/MED | C6: lento | D6: =IFERROR(AVERAGE('Directivo 1'!D6,'Directivo 2'!D6,'Directivo 3'!D6,'Directivo 4'!D6,'Directivo 5'!D6),"") | E6: =IFERROR(AVERAGE('Directivo 1'!E6,'Directivo 2'!E6,'Directivo 3'!E6,'Directivo 4'!E6,'Directivo 5'!E6),"") | F6: =IFERROR(AVERAGE('Directivo 1'!F6,'Directivo 2'!F6,'Directivo 3'!F6,'Directivo 4'!F6,'Directivo 5'!F6),"") | G6: =IFERROR(AVERAGE('Directivo 1'!G6,'Directivo 2'!G6,'Directivo 3'!G6,'Directivo 4'!G6,'Directivo 5'!G6),"") | H6: =IFERROR(AVERAGE('Directivo 1'!H6,'Directivo 2'!H6,'Directivo 3'!H6,'Directivo 4'!H6,'Directivo 5'!H6),"") | I6: =IFERROR(AVERAGE('Directivo 1'!I6,'Directivo 2'!I6,'Directivo 3'!I6,'Directivo 4'!I6,'Directivo 5'!I6),"") | J6: =IFERROR(AVERAGE('Directivo 1'!J6,'Directivo 2'!J6,'Directivo 3'!J6,'Directivo 4'!J6,'Directivo 5'!J6),"") | K6: =IFERROR(AVERAGE('Directivo 1'!K6,'Directivo 2'!K6,'Directivo 3'!K6,'Directivo 4'!K6,'Directivo 5'!K6),"") | L6: =TEXTJOIN(" | ",TRUE,'Directivo 1'!L6,'Directivo 2'!L6,'Directivo 3'!L6,'Directivo 4'!L6,'Directivo 5'!L6)
A7: BRIAN | B7: DEL/MED | C7: rapido | D7: =IFERROR(AVERAGE('Directivo 1'!D7,'Directivo 2'!D7,'Directivo 3'!D7,'Directivo 4'!D7,'Directivo 5'!D7),"") | E7: =IFERROR(AVERAGE('Directivo 1'!E7,'Directivo 2'!E7,'Directivo 3'!E7,'Directivo 4'!E7,'Directivo 5'!E7),"") | F7: =IFERROR(AVERAGE('Directivo 1'!F7,'Directivo 2'!F7,'Directivo 3'!F7,'Directivo 4'!F7,'Directivo 5'!F7),"") | G7: =IFERROR(AVERAGE('Directivo 1'!G7,'Directivo 2'!G7,'Directivo 3'!G7,'Directivo 4'!G7,'Directivo 5'!G7),"") | H7: =IFERROR(AVERAGE('Directivo 1'!H7,'Directivo 2'!H7,'Directivo 3'!H7,'Directivo 4'!H7,'Directivo 5'!H7),"") | I7: =IFERROR(AVERAGE('Directivo 1'!I7,'Directivo 2'!I7,'Directivo 3'!I7,'Directivo 4'!I7,'Directivo 5'!I7),"") | J7: =IFERROR(AVERAGE('Directivo 1'!J7,'Directivo 2'!J7,'Directivo 3'!J7,'Directivo 4'!J7,'Directivo 5'!J7),"") | K7: =IFERROR(AVERAGE('Directivo 1'!K7,'Directivo 2'!K7,'Directivo 3'!K7,'Directivo 4'!K7,'Directivo 5'!K7),"") | L7: =TEXTJOIN(" | ",TRUE,'Directivo 1'!L7,'Directivo 2'!L7,'Directivo 3'!L7,'Directivo 4'!L7,'Directivo 5'!L7)
A8: CAMILO | B8: MED/DEL | C8: rapido | D8: =IFERROR(AVERAGE('Directivo 1'!D8,'Directivo 2'!D8,'Directivo 3'!D8,'Directivo 4'!D8,'Directivo 5'!D8),"") | E8: =IFERROR(AVERAGE('Directivo 1'!E8,'Directivo 2'!E8,'Directivo 3'!E8,'Directivo 4'!E8,'Directivo 5'!E8),"") | F8: =IFERROR(AVERAGE('Directivo 1'!F8,'Directivo 2'!F8,'Directivo 3'!F8,'Directivo 4'!F8,'Directivo 5'!F8),"") | G8: =IFERROR(AVERAGE('Directivo 1'!G8,'Directivo 2'!G8,'Directivo 3'!G8,'Directivo 4'!G8,'Directivo 5'!G8),"") | H8: =IFERROR(AVERAGE('Directivo 1'!H8,'Directivo 2'!H8,'Directivo 3'!H8,'Directivo 4'!H8,'Directivo 5'!H8),"") | I8: =IFERROR(AVERAGE('Directivo 1'!I8,'Directivo 2'!I8,'Directivo 3'!I8,'Directivo 4'!I8,'Directivo 5'!I8),"") | J8: =IFERROR(AVERAGE('Directivo 1'!J8,'Directivo 2'!J8,'Directivo 3'!J8,'Directivo 4'!J8,'Directivo 5'!J8),"") | K8: =IFERROR(AVERAGE('Directivo 1'!K8,'Directivo 2'!K8,'Directivo 3'!K8,'Directivo 4'!K8,'Directivo 5'!K8),"") | L8: =TEXTJOIN(" | ",TRUE,'Directivo 1'!L8,'Directivo 2'!L8,'Directivo 3'!L8,'Directivo 4'!L8,'Directivo 5'!L8)
A9: CESAR | B9: DEF/LAT | C9: rapido | D9: =IFERROR(AVERAGE('Directivo 1'!D9,'Directivo 2'!D9,'Directivo 3'!D9,'Directivo 4'!D9,'Directivo 5'!D9),"") | E9: =IFERROR(AVERAGE('Directivo 1'!E9,'Directivo 2'!E9,'Directivo 3'!E9,'Directivo 4'!E9,'Directivo 5'!E9),"") | F9: =IFERROR(AVERAGE('Directivo 1'!F9,'Directivo 2'!F9,'Directivo 3'!F9,'Directivo 4'!F9,'Directivo 5'!F9),"") | G9: =IFERROR(AVERAGE('Directivo 1'!G9,'Directivo 2'!G9,'Directivo 3'!G9,'Directivo 4'!G9,'Directivo 5'!G9),"") | H9: =IFERROR(AVERAGE('Directivo 1'!H9,'Directivo 2'!H9,'Directivo 3'!H9,'Directivo 4'!H9,'Directivo 5'!H9),"") | I9: =IFERROR(AVERAGE('Directivo 1'!I9,'Directivo 2'!I9,'Directivo 3'!I9,'Directivo 4'!I9,'Directivo 5'!I9),"") | J9: =IFERROR(AVERAGE('Directivo 1'!J9,'Directivo 2'!J9,'Directivo 3'!J9,'Directivo 4'!J9,'Directivo 5'!J9),"") | K9: =IFERROR(AVERAGE('Directivo 1'!K9,'Directivo 2'!K9,'Directivo 3'!K9,'Directivo 4'!K9,'Directivo 5'!K9),"") | L9: =TEXTJOIN(" | ",TRUE,'Directivo 1'!L9,'Directivo 2'!L9,'Directivo 3'!L9,'Directivo 4'!L9,'Directivo 5'!L9)
A10: COMANCHE | B10: LAT/MED | C10: lento | D10: =IFERROR(AVERAGE('Directivo 1'!D10,'Directivo 2'!D10,'Directivo 3'!D10,'Directivo 4'!D10,'Directivo 5'!D10),"") | E10: =IFERROR(AVERAGE('Directivo 1'!E10,'Directivo 2'!E10,'Directivo 3'!E10,'Directivo 4'!E10,'Directivo 5'!E10),"") | F10: =IFERROR(AVERAGE('Directivo 1'!F10,'Directivo 2'!F10,'Directivo 3'!F10,'Directivo 4'!F10,'Directivo 5'!F10),"") | G10: =IFERROR(AVERAGE('Directivo 1'!G10,'Directivo 2'!G10,'Directivo 3'!G10,'Directivo 4'!G10,'Directivo 5'!G10),"") | H10: =IFERROR(AVERAGE('Directivo 1'!H10,'Directivo 2'!H10,'Directivo 3'!H10,'Directivo 4'!H10,'Directivo 5'!H10),"") | I10: =IFERROR(AVERAGE('Directivo 1'!I10,'Directivo 2'!I10,'Directivo 3'!I10,'Directivo 4'!I10,'Directivo 5'!I10),"") | J10: =IFERROR(AVERAGE('Directivo 1'!J10,'Directivo 2'!J10,'Directivo 3'!J10,'Directivo 4'!J10,'Directivo 5'!J10),"") | K10: =IFERROR(AVERAGE('Directivo 1'!K10,'Directivo 2'!K10,'Directivo 3'!K10,'Directivo 4'!K10,'Directivo 5'!K10),"") | L10: =TEXTJOIN(" | ",TRUE,'Directivo 1'!L10,'Directivo 2'!L10,'Directivo 3'!L10,'Directivo 4'!L10,'Directivo 5'!L10)
A11: CRISTIAN | B11: DEL/ARQ | C11: lento | D11: =IFERROR(AVERAGE('Directivo 1'!D11,'Directivo 2'!D11,'Directivo 3'!D11,'Directivo 4'!D11,'Directivo 5'!D11),"") | E11: =IFERROR(AVERAGE('Directivo 1'!E11,'Directivo 2'!E11,'Directivo 3'!E11,'Directivo 4'!E11,'Directivo 5'!E11),"") | F11: =IFERROR(AVERAGE('Directivo 1'!F11,'Directivo 2'!F11,'Directivo 3'!F11,'Directivo 4'!F11,'Directivo 5'!F11),"") | G11: =IFERROR(AVERAGE('Directivo 1'!G11,'Directivo 2'!G11,'Directivo 3'!G11,'Directivo 4'!G11,'Directivo 5'!G11),"") | H11: =IFERROR(AVERAGE('Directivo 1'!H11,'Directivo 2'!H11,'Directivo 3'!H11,'Directivo 4'!H11,'Directivo 5'!H11),"") | I11: =IFERROR(AVERAGE('Directivo 1'!I11,'Directivo 2'!I11,'Directivo 3'!I11,'Directivo 4'!I11,'Directivo 5'!I11),"") | J11: =IFERROR(AVERAGE('Directivo 1'!J11,'Directivo 2'!J11,'Directivo 3'!J11,'Directivo 4'!J11,'Directivo 5'!J11),"") | K11: =IFERROR(AVERAGE('Directivo 1'!K11,'Directivo 2'!K11,'Directivo 3'!K11,'Directivo 4'!K11,'Directivo 5'!K11),"") | L11: =TEXTJOIN(" | ",TRUE,'Directivo 1'!L11,'Directivo 2'!L11,'Directivo 3'!L11,'Directivo 4'!L11,'Directivo 5'!L11)
A12: CUERVO | B12: DEL/DEF | C12: rapido | D12: =IFERROR(AVERAGE('Directivo 1'!D12,'Directivo 2'!D12,'Directivo 3'!D12,'Directivo 4'!D12,'Directivo 5'!D12),"") | E12: =IFERROR(AVERAGE('Directivo 1'!E12,'Directivo 2'!E12,'Directivo 3'!E12,'Directivo 4'!E12,'Directivo 5'!E12),"") | F12: =IFERROR(AVERAGE('Directivo 1'!F12,'Directivo 2'!F12,'Directivo 3'!F12,'Directivo 4'!F12,'Directivo 5'!F12),"") | G12: =IFERROR(AVERAGE('Directivo 1'!G12,'Directivo 2'!G12,'Directivo 3'!G12,'Directivo 4'!G12,'Directivo 5'!G12),"") | H12: =IFERROR(AVERAGE('Directivo 1'!H12,'Directivo 2'!H12,'Directivo 3'!H12,'Directivo 4'!H12,'Directivo 5'!H12),"") | I12: =IFERROR(AVERAGE('Directivo 1'!I12,'Directivo 2'!I12,'Directivo 3'!I12,'Directivo 4'!I12,'Directivo 5'!I12),"") | J12: =IFERROR(AVERAGE('Directivo 1'!J12,'Directivo 2'!J12,'Directivo 3'!J12,'Directivo 4'!J12,'Directivo 5'!J12),"") | K12: =IFERROR(AVERAGE('Directivo 1'!K12,'Directivo 2'!K12,'Directivo 3'!K12,'Directivo 4'!K12,'Directivo 5'!K12),"") | L12: =TEXTJOIN(" | ",TRUE,'Directivo 1'!L12,'Directivo 2'!L12,'Directivo 3'!L12,'Directivo 4'!L12,'Directivo 5'!L12)
A13: ELIAN | B13: DEF/DEL | C13: lento | D13: =IFERROR(AVERAGE('Directivo 1'!D13,'Directivo 2'!D13,'Directivo 3'!D13,'Directivo 4'!D13,'Directivo 5'!D13),"") | E13: =IFERROR(AVERAGE('Directivo 1'!E13,'Directivo 2'!E13,'Directivo 3'!E13,'Directivo 4'!E13,'Directivo 5'!E13),"") | F13: =IFERROR(AVERAGE('Directivo 1'!F13,'Directivo 2'!F13,'Directivo 3'!F13,'Directivo 4'!F13,'Directivo 5'!F13),"") | G13: =IFERROR(AVERAGE('Directivo 1'!G13,'Directivo 2'!G13,'Directivo 3'!G13,'Directivo 4'!G13,'Directivo 5'!G13),"") | H13: =IFERROR(AVERAGE('Directivo 1'!H13,'Directivo 2'!H13,'Directivo 3'!H13,'Directivo 4'!H13,'Directivo 5'!H13),"") | I13: =IFERROR(AVERAGE('Directivo 1'!I13,'Directivo 2'!I13,'Directivo 3'!I13,'Directivo 4'!I13,'Directivo 5'!I13),"") | J13: =IFERROR(AVERAGE('Directivo 1'!J13,'Directivo 2'!J13,'Directivo 3'!J13,'Directivo 4'!J13,'Directivo 5'!J13),"") | K13: =IFERROR(AVERAGE('Directivo 1'!K13,'Directivo 2'!K13,'Directivo 3'!K13,'Directivo 4'!K13,'Directivo 5'!K13),"") | L13: =TEXTJOIN(" | ",TRUE,'Directivo 1'!L13,'Directivo 2'!L13,'Directivo 3'!L13,'Directivo 4'!L13,'Directivo 5'!L13)
... A43: VIKINGO | B43: MED/LAT | C43: rapido | D43: =IFERROR(AVERAGE('Directivo 1'!D43,'Directivo 2'!D43,'Directivo 3'!D43,'Directivo 4'!D43,'Directivo 5'!D43),"") | E43: =IFERROR(AVERAGE('Directivo 1'!E43,'Directivo 2'!E43,'Directivo 3'!E43,'Directivo 4'!E43,'Directivo 5'!E43),"") | F43: =IFERROR(AVERAGE('Directivo 1'!F43,'Directivo 2'!F43,'Directivo 3'!F43,'Directivo 4'!F43,'Directivo 5'!F43),"") | G43: =IFERROR(AVERAGE('Directivo 1'!G43,'Directivo 2'!G43,'Directivo 3'!G43,'Directivo 4'!G43,'Directivo 5'!G43),"") | H43: =IFERROR(AVERAGE('Directivo 1'!H43,'Directivo 2'!H43,'Directivo 3'!H43,'Directivo 4'!H43,'Directivo 5'!H43),"") | I43: =IFERROR(AVERAGE('Directivo 1'!I43,'Directivo 2'!I43,'Directivo 3'!I43,'Directivo 4'!I43,'Directivo 5'!I43),"") | J43: =IFERROR(AVERAGE('Directivo 1'!J43,'Directivo 2'!J43,'Directivo 3'!J43,'Directivo 4'!J43,'Directivo 5'!J43),"") | K43: =IFERROR(AVERAGE('Directivo 1'!K43,'Directivo 2'!K43,'Directivo 3'!K43,'Directivo 4'!K43,'Directivo 5'!K43),"") | L43: =TEXTJOIN(" | ",TRUE,'Directivo 1'!L43,'Directivo 2'!L43,'Directivo 3'!L43,'Directivo 4'!L43,'Directivo 5'!L43)

Sheet Directivo 1
A1: Nombre jugador | B1: Posiciones | C1: Ritmo base | D1: Ataque | E1: Solidez | F1: Tecnica | G1: Ritmo | H1: Equipo | I1: Mentalidad | J1: Regularidad | K1: Arquero | L1: Comentarios
A2: ALE CUERVO | B2: LAT/MED | C2: lento | D2: 2.8 | E2: 2.6 | F2: 3.3 | G2: 3 | H2: 3 | I2: 2.2 | J2: 2.8 | K2: 3.6
A3: ALEXIS | B3: LAT/MED | C3: rapido | D3: 3.6 | E3: 3.6 | F3: 3.9 | G3: 4.8 | H3: 3.3 | I3: 4.3 | J3: 4.8 | K3: 3.3
A4: ANIBAL | B4: DEL | C4: lento | D4: 3.7 | E4: 1.8 | F4: 3.6 | G4: 1.4 | H4: 1.8 | I4: 2.2 | J4: 2.8 | K4: 4.3
A5: AUGUSTO | B5: MED/LAT | C5: rapido | D5: 3.7 | E5: 3.3 | F5: 4.3 | G5: 4.3 | H5: 3.9 | I5: 2.8 | J5: 2.6 | K5: 3.6
A6: BETO | B6: DEL/MED | C6: lento | D6: 3.7 | E6: 1.8 | F6: 3.6 | G6: 2.2 | H6: 3 | I6: 3.6 | J6: 4 | K6: 3.3
A7: BRIAN | B7: DEL/MED | C7: rapido | D7: 5.4 | E7: 3.9 | F7: 5.4 | G7: 3.9 | H7: 4.3 | I7: 2.8 | J7: 4.8
A8: CAMILO | B8: MED/DEL | C8: rapido | D8: 3.9 | E8: 3 | F8: 5 | G8: 4.3 | H8: 4 | I8: 4 | J8: 4 | K8: 3.3
A9: CESAR | B9: DEF/LAT | C9: rapido | D9: 3.6 | E9: 4.6 | F9: 4.3 | G9: 3.3 | H9: 4.1 | I9: 3.6 | J9: 4.8
A10: COMANCHE | B10: LAT/MED | C10: lento | D10: 2.8 | E10: 2.7 | F10: 3.6 | G10: 2 | H10: 1.8 | I10: 3 | J10: 3 | K10: 3.9
A11: CRISTIAN | B11: DEL/ARQ | C11: lento | D11: 2.6 | E11: 1.4 | F11: 2.8 | G11: 2.2 | H11: 2.8 | I11: 3.9 | J11: 2.8 | K11: 3.6
A12: CUERVO | B12: DEL/DEF | C12: rapido | D12: 6 | E12: 3.6 | F12: 5.4 | G12: 3.6 | H12: 2.8 | I12: 3.3 | J12: 2.8
A13: ELIAN | B13: DEF/DEL | C13: lento | D13: 2.2 | E13: 1.4 | F13: 2.9 | G13: 1.4 | H13: 2.8 | I13: 2.8 | J13: 2 | K13: 3.3
A14: FACU | B14: DEF/DEL | C14: lento | D14: 2.6 | E14: 4.1 | F14: 2.9 | G14: 2.8 | H14: 3 | I14: 2.6 | J14: 3.9 | K14: 2.8
A15: FRANCISCO | B15: ARQ/DEL | C15: lento | D15: 1.4 | E15: 2.2 | F15: 1.4 | G15: 3 | H15: 2.2 | I15: 3.6 | J15: 2.8 | K15: 3.6
A16: FRANCO COMOLLI | B16: MED/DEL | C16: rapido | D16: 4.3 | E16: 4.3 | F16: 5 | G16: 4.8 | H16: 4.8 | I16: 4.8 | J16: 5.4 | K16: 3.3
A17: FRANCOK | B17: ARQ/LAT | C17: rapido | D17: 1.4 | E17: 2.8 | F17: 2.6 | G17: 3.6 | H17: 3 | I17: 3 | J17: 3.3 | K17: 3.9
A18: FRANQUITO | B18: MED | C18: rapido | D18: 3.4 | E18: 3 | F18: 3.9 | G18: 4.3 | H18: 3.3 | I18: 3.3 | J18: 4 | K18: 3.6
A19: GONZA | B19: ARQ/DEF | C19: lento | D19: 2.6 | E19: 3.9 | F19: 3 | G19: 3 | H19: 3.3 | I19: 3.3 | J19: 3.9 | K19: 3.9
A20: GUILLE | B20: LAT/ARQ | C20: lento | D20: 2.2 | E20: 1.4 | F20: 2.6 | G20: 1.4 | H20: 2.8 | I20: 3.9 | J20: 2.8 | K20: 3.3
A21: ISMA | B21: MED/LAT | C21: rapido | D21: 3.6 | E21: 3.9 | F21: 4.8 | G21: 3.9 | H21: 4.6 | I21: 4.3 | J21: 4.3 | K21: 3.6
A22: JAVI | B22: DEF/ARQ | C22: lento | D22: 2.8 | E22: 3.7 | F22: 3.2 | G22: 3 | H22: 3.3 | I22: 3.9 | J22: 3 | K22: 4.8
A23: JEAN FRANCO | B23: DEL | C23: lento | D23: 2 | E23: 2 | F23: 3 | G23: 3 | H23: 3 | I23: 4 | J23: 2.2 | K23: 2.6
A24: MANU | B24: LAT/MED | C24: rapido | D24: 4.2 | E24: 4.8 | F24: 4.3 | G24: 6 | H24: 4.3 | I24: 3.3 | J24: 4.8
A25: MARCELO | B25: MED/LAT | C25: lento | D25: 2.7 | E25: 1.8 | F25: 3.7 | G25: 2.2 | H25: 4.2 | I25: 1.4 | J25: 2.6 | K25: 3.3
A26: MARIAN | B26: DEL/MED | C26: lento | D26: 4.3 | E26: 1.8 | F26: 4.1 | G26: 2.2 | H26: 3.6 | I26: 2.8 | J26: 3.3 | K26: 3.9
A27: MATI BRAIAN | B27: DEF/MED | C27: rapido | D27: 3.6 | E27: 3.3 | F27: 3.9 | G27: 4.8 | H27: 2.6 | I27: 2.8 | J27: 3.3 | K27: 3.4
A28: MATI ROSALES | B28: MED/LAT | C28: rapido | D28: 3.9 | E28: 4.1 | F28: 6 | G28: 3.6 | H28: 5.4 | I28: 3.9 | J28: 4.3
A29: MAURI | B29: DEL | C29: rapido | D29: 3.9 | E29: 2.6 | F29: 3.3 | G29: 4 | H29: 3.3 | I29: 3.9 | J29: 3.6 | K29: 3.3
A30: MAXI | B30: MED | C30: lento | D30: 2.8 | E30: 1.8 | F30: 3.6 | G30: 2 | H30: 3 | I30: 2.8 | J30: 2.2 | K30: 2.5
A31: NICO | B31: MED/LAT | C31: rapido | D31: 3.9 | E31: 2.6 | F31: 3.9 | G31: 3.3 | H31: 3.9 | I31: 3.3 | J31: 3.3 | K31: 3.3
A32: PABLO | B32: DEF/LAT | C32: rapido | D32: 3 | E32: 5 | F32: 3.9 | G32: 3.9 | H32: 3.9 | I32: 5.4 | J32: 5.4
A33: PABLO CASTILLO | B33: LAT/MED | C33: lento | D33: 3 | E33: 3.9 | F33: 3.9 | G33: 3 | H33: 4.3 | I33: 3.6 | J33: 3 | K33: 3.3
A34: PABLO GARCIA | B34: MED/LAT | C34: rapido | D34: 2.3 | E34: 3 | F34: 2.7 | G34: 3.3 | H34: 3.3 | I34: 4.3 | J34: 3.9 | K34: 3.3
A35: PELA | B35: DEL/MED | C35: rapido | D35: 4.3 | E35: 3.6 | F35: 4.3 | G35: 3.6 | H35: 2.8 | I35: 4.3 | J35: 2.2 | K35: 3.6
A36: PULY | B36: DEL/MED | C36: lento | D36: 3 | E36: 1 | F36: 5 | G36: 2.2 | H36: 3 | I36: 2.2 | J36: 2.2 | K36: 3.3
A37: RODRI CHAVEZ | B37: LAT/MED | C37: rapido | D37: 3.6 | E37: 4.1 | F37: 3.9 | G37: 4.3 | H37: 4.3 | I37: 4.8 | J37: 4.8 | K37: 3.6
A38: RODRI SUAREZ | B38: DEF/ARQ | C38: lento | D38: 2.2 | E38: 3.7 | F38: 2.8 | G38: 3 | H38: 3.6 | I38: 3.9 | J38: 3.9 | K38: 3.9
A39: SANTI | B39: ARQ/MED | C39: rapido | D39: 3 | E39: 3 | F39: 5 | G39: 4 | H39: 3 | I39: 3 | J39: 4 | K39: 3.3
A40: SEBACORTEZ | B40: DEF/ARQ | C40: lento | D40: 3.3 | E40: 4.1 | F40: 3.9 | G40: 2.8 | H40: 3.6 | I40: 4.3 | J40: 3 | K40: 4.8
...

Sheet Directivo 2
A1: Nombre jugador | B1: Posiciones | C1: Ritmo base | D1: Ataque | E1: Solidez | F1: Tecnica | G1: Ritmo | H1: Equipo | I1: Mentalidad | J1: Regularidad | K1: Arquero | L1: Comentarios
A2: ALE CUERVO | B2: LAT/MED | C2: lento | D2: 2.8 | E2: 2.6 | F2: 3.3 | G2: 3 | H2: 3 | I2: 2.2 | J2: 2.8 | K2: 3.6
A3: ALEXIS | B3: LAT/MED | C3: rapido | D3: 3.6 | E3: 3.6 | F3: 3.9 | G3: 4.8 | H3: 3.3 | I3: 4.3 | J3: 4.8 | K3: 3.3
A4: ANIBAL | B4: DEL | C4: lento | D4: 3.7 | E4: 1.8 | F4: 3.6 | G4: 1.4 | H4: 1.8 | I4: 2.2 | J4: 2.8 | K4: 4.3
A5: AUGUSTO | B5: MED/LAT | C5: rapido | D5: 3.7 | E5: 3.3 | F5: 4.3 | G5: 4.3 | H5: 3.9 | I5: 2.8 | J5: 2.6 | K5: 3.6
A6: BETO | B6: DEL/MED | C6: lento | D6: 3.7 | E6: 1.8 | F6: 3.6 | G6: 2.2 | H6: 3 | I6: 3.6 | J6: 4 | K6: 3.3
A7: BRIAN | B7: DEL/MED | C7: rapido | D7: 5.4 | E7: 3.9 | F7: 5.4 | G7: 3.9 | H7: 4.3 | I7: 2.8 | J7: 4.8
A8: CAMILO | B8: MED/DEL | C8: rapido | D8: 3.9 | E8: 3 | F8: 5 | G8: 4.3 | H8: 4 | I8: 4 | J8: 4 | K8: 3.3
A9: CESAR | B9: DEF/LAT | C9: rapido | D9: 3.6 | E9: 4.6 | F9: 4.3 | G9: 3.3 | H9: 4.1 | I9: 3.6 | J9: 4.8
A10: COMANCHE | B10: LAT/MED | C10: lento | D10: 2.8 | E10: 2.7 | F10: 3.6 | G10: 2 | H10: 1.8 | I10: 3 | J10: 3 | K10: 3.9
A11: CRISTIAN | B11: DEL/ARQ | C11: lento | D11: 2.6 | E11: 1.4 | F11: 2.8 | G11: 2.2 | H11: 2.8 | I11: 3.9 | J11: 2.8 | K11: 3.6
A12: CUERVO | B12: DEL/DEF | C12: rapido | D12: 6 | E12: 3.6 | F12: 5.4 | G12: 3.6 | H12: 2.8 | I12: 3.3 | J12: 2.8
A13: ELIAN | B13: DEF/DEL | C13: lento | D13: 2.2 | E13: 1.4 | F13: 2.9 | G13: 1.4 | H13: 2.8 | I13: 2.8 | J13: 2 | K13: 3.3
A14: FACU | B14: DEF/DEL | C14: lento | D14: 2.6 | E14: 4.1 | F14: 2.9 | G14: 2.8 | H14: 3 | I14: 2.6 | J14: 3.9 | K14: 2.8
A15: FRANCISCO | B15: ARQ/DEL | C15: lento | D15: 1.4 | E15: 2.2 | F15: 1.4 | G15: 3 | H15: 2.2 | I15: 3.6 | J15: 2.8 | K15: 3.6
A16: FRANCO COMOLLI | B16: MED/DEL | C16: rapido | D16: 4.3 | E16: 4.3 | F16: 5 | G16: 4.8 | H16: 4.8 | I16: 4.8 | J16: 5.4 | K16: 3.3
A17: FRANCOK | B17: ARQ/LAT | C17: rapido | D17: 1.4 | E17: 2.8 | F17: 2.6 | G17: 3.6 | H17: 3 | I17: 3 | J17: 3.3 | K17: 3.9
A18: FRANQUITO | B18: MED | C18: rapido | D18: 3.4 | E18: 3 | F18: 3.9 | G18: 4.3 | H18: 3.3 | I18: 3.3 | J18: 4 | K18: 3.6
A19: GONZA | B19: ARQ/DEF | C19: lento | D19: 2.6 | E19: 3.9 | F19: 3 | G19: 3 | H19: 3.3 | I19: 3.3 | J19: 3.9 | K19: 3.9
A20: GUILLE | B20: LAT/ARQ | C20: lento | D20: 2.2 | E20: 1.4 | F20: 2.6 | G20: 1.4 | H20: 2.8 | I20: 3.9 | J20: 2.8 | K20: 3.3
A21: ISMA | B21: MED/LAT | C21: rapido | D21: 3.6 | E21: 3.9 | F21: 4.8 | G21: 3.9 | H21: 4.6 | I21: 4.3 | J21: 4.3 | K21: 3.6
A22: JAVI | B22: DEF/ARQ | C22: lento | D22: 2.8 | E22: 3.7 | F22: 3.2 | G22: 3 | H22: 3.3 | I22: 3.9 | J22: 3 | K22: 4.8
A23: JEAN FRANCO | B23: DEL | C23: lento | D23: 2 | E23: 2 | F23: 3 | G23: 3 | H23: 3 | I23: 4 | J23: 2.2 | K23: 2.6
A24: MANU | B24: LAT/MED | C24: rapido | D24: 4.2 | E24: 4.8 | F24: 4.3 | G24: 6 | H24: 4.3 | I24: 3.3 | J24: 4.8
A25: MARCELO | B25: MED/LAT | C25: lento | D25: 2.7 | E25: 1.8 | F25: 3.7 | G25: 2.2 | H25: 4.2 | I25: 1.4 | J25: 2.6 | K25: 3.3
A26: MARIAN | B26: DEL/MED | C26: lento | D26: 4.3 | E26: 1.8 | F26: 4.1 | G26: 2.2 | H26: 3.6 | I26: 2.8 | J26: 3.3 | K26: 3.9
A27: MATI BRAIAN | B27: DEF/MED | C27: rapido | D27: 3.6 | E27: 3.3 | F27: 3.9 | G27: 4.8 | H27: 2.6 | I27: 2.8 | J27: 3.3 | K27: 3.4
A28: MATI ROSALES | B28: MED/LAT | C28: rapido | D28: 3.9 | E28: 4.1 | F28: 6 | G28: 3.6 | H28: 5.4 | I28: 3.9 | J28: 4.3
A29: MAURI | B29: DEL | C29: rapido | D29: 3.9 | E29: 2.6 | F29: 3.3 | G29: 4 | H29: 3.3 | I29: 3.9 | J29: 3.6 | K29: 3.3
A30: MAXI | B30: MED | C30: lento | D30: 2.8 | E30: 1.8 | F30: 3.6 | G30: 2 | H30: 3 | I30: 2.8 | J30: 2.2 | K30: 2.5
A31: NICO | B31: MED/LAT | C31: rapido | D31: 3.9 | E31: 2.6 | F31: 3.9 | G31: 3.3 | H31: 3.9 | I31: 3.3 | J31: 3.3 | K31: 3.3
A32: PABLO | B32: DEF/LAT | C32: rapido | D32: 3 | E32: 5 | F32: 3.9 | G32: 3.9 | H32: 3.9 | I32: 5.4 | J32: 5.4
A33: PABLO CASTILLO | B33: LAT/MED | C33: lento | D33: 3 | E33: 3.9 | F33: 3.9 | G33: 3 | H33: 4.3 | I33: 3.6 | J33: 3 | K33: 3.3
A34: PABLO GARCIA | B34: MED/LAT | C34: rapido | D34: 2.3 | E34: 3 | F34: 2.7 | G34: 3.3 | H34: 3.3 | I34: 4.3 | J34: 3.9 | K34: 3.3
A35: PELA | B35: DEL/MED | C35: rapido | D35: 4.3 | E35: 3.6 | F35: 4.3 | G35: 3.6 | H35: 2.8 | I35: 4.3 | J35: 2.2 | K35: 3.6
A36: PULY | B36: DEL/MED | C36: lento | D36: 3 | E36: 1 | F36: 5 | G36: 2.2 | H36: 3 | I36: 2.2 | J36: 2.2 | K36: 3.3
A37: RODRI CHAVEZ | B37: LAT/MED | C37: rapido | D37: 3.6 | E37: 4.1 | F37: 3.9 | G37: 4.3 | H37: 4.3 | I37: 4.8 | J37: 4.8 | K37: 3.6
A38: RODRI SUAREZ | B38: DEF/ARQ | C38: lento | D38: 2.2 | E38: 3.7 | F38: 2.8 | G38: 3 | H38: 3.6 | I38: 3.9 | J38: 3.9 | K38: 3.9
A39: SANTI | B39: ARQ/MED | C39: rapido | D39: 3 | E39: 3 | F39: 5 | G39: 4 | H39: 3 | I39: 3 | J39: 4 | K39: 3.3
A40: SEBACORTEZ | B40: DEF/ARQ | C40: lento | D40: 3.3 | E40: 4.1 | F40: 3.9 | G40: 2.8 | H40: 3.6 | I40: 4.3 | J40: 3 | K40: 4.8
...

Sheet Directivo 3
A1: Nombre jugador | B1: Posiciones | C1: Ritmo base | D1: Ataque | E1: Solidez | F1: Tecnica | G1: Ritmo | H1: Equipo | I1: Mentalidad | J1: Regularidad | K1: Arquero | L1: Comentarios
A2: ALE CUERVO | B2: LAT/MED | C2: lento | D2: 2.8 | E2: 2.6 | F2: 3.3 | G2: 3 | H2: 3 | I2: 2.2 | J2: 2.8 | K2: 3.6
A3: ALEXIS | B3: LAT/MED | C3: rapido | D3: 3.6 | E3: 3.6 | F3: 3.9 | G3: 4.8 | H3: 3.3 | I3: 4.3 | J3: 4.8 | K3: 3.3
A4: ANIBAL | B4: DEL | C4: lento | D4: 3.7 | E4: 1.8 | F4: 3.6 | G4: 1.4 | H4: 1.8 | I4: 2.2 | J4: 2.8 | K4: 4.3
A5: AUGUSTO | B5: MED/LAT | C5: rapido | D5: 3.7 | E5: 3.3 | F5: 4.3 | G5: 4.3 | H5: 3.9 | I5: 2.8 | J5: 2.6 | K5: 3.6
A6: BETO | B6: DEL/MED | C6: lento | D6: 3.7 | E6: 1.8 | F6: 3.6 | G6: 2.2 | H6: 3 | I6: 3.6 | J6: 4 | K6: 3.3
A7: BRIAN | B7: DEL/MED | C7: rapido | D7: 5.4 | E7: 3.9 | F7: 5.4 | G7: 3.9 | H7: 4.3 | I7: 2.8 | J7: 4.8
A8: CAMILO | B8: MED/DEL | C8: rapido | D8: 3.9 | E8: 3 | F8: 5 | G8: 4.3 | H8: 4 | I8: 4 | J8: 4 | K8: 3.3
A9: CESAR | B9: DEF/LAT | C9: rapido | D9: 3.6 | E9: 4.6 | F9: 4.3 | G9: 3.3 | H9: 4.1 | I9: 3.6 | J9: 4.8
A10: COMANCHE | B10: LAT/MED | C10: lento | D10: 2.8 | E10: 2.7 | F10: 3.6 | G10: 2 | H10: 1.8 | I10: 3 | J10: 3 | K10: 3.9
A11: CRISTIAN | B11: DEL/ARQ | C11: lento | D11: 2.6 | E11: 1.4 | F11: 2.8 | G11: 2.2 | H11: 2.8 | I11: 3.9 | J11: 2.8 | K11: 3.6
A12: CUERVO | B12: DEL/DEF | C12: rapido | D12: 6 | E12: 3.6 | F12: 5.4 | G12: 3.6 | H12: 2.8 | I12: 3.3 | J12: 2.8
A13: ELIAN | B13: DEF/DEL | C13: lento | D13: 2.2 | E13: 1.4 | F13: 2.9 | G13: 1.4 | H13: 2.8 | I13: 2.8 | J13: 2 | K13: 3.3
A14: FACU | B14: DEF/DEL | C14: lento | D14: 2.6 | E14: 4.1 | F14: 2.9 | G14: 2.8 | H14: 3 | I14: 2.6 | J14: 3.9 | K14: 2.8
A15: FRANCISCO | B15: ARQ/DEL | C15: lento | D15: 1.4 | E15: 2.2 | F15: 1.4 | G15: 3 | H15: 2.2 | I15: 3.6 | J15: 2.8 | K15: 3.6
A16: FRANCO COMOLLI | B16: MED/DEL | C16: rapido | D16: 4.3 | E16: 4.3 | F16: 5 | G16: 4.8 | H16: 4.8 | I16: 4.8 | J16: 5.4 | K16: 3.3
A17: FRANCOK | B17: ARQ/LAT | C17: rapido | D17: 1.4 | E17: 2.8 | F17: 2.6 | G17: 3.6 | H17: 3 | I17: 3 | J17: 3.3 | K17: 3.9
A18: FRANQUITO | B18: MED | C18: rapido | D18: 3.4 | E18: 3 | F18: 3.9 | G18: 4.3 | H18: 3.3 | I18: 3.3 | J18: 4 | K18: 3.6
A19: GONZA | B19: ARQ/DEF | C19: lento | D19: 2.6 | E19: 3.9 | F19: 3 | G19: 3 | H19: 3.3 | I19: 3.3 | J19: 3.9 | K19: 3.9
A20: GUILLE | B20: LAT/ARQ | C20: lento | D20: 2.2 | E20: 1.4 | F20: 2.6 | G20: 1.4 | H20: 2.8 | I20: 3.9 | J20: 2.8 | K20: 3.3
A21: ISMA | B21: MED/LAT | C21: rapido | D21: 3.6 | E21: 3.9 | F21: 4.8 | G21: 3.9 | H21: 4.6 | I21: 4.3 | J21: 4.3 | K21: 3.6
A22: JAVI | B22: DEF/ARQ | C22: lento | D22: 2.8 | E22: 3.7 | F22: 3.2 | G22: 3 | H22: 3.3 | I22: 3.9 | J22: 3 | K22: 4.8
A23: JEAN FRANCO | B23: DEL | C23: lento | D23: 2 | E23: 2 | F23: 3 | G23: 3 | H23: 3 | I23: 4 | J23: 2.2 | K23: 2.6
A24: MANU | B24: LAT/MED | C24: rapido | D24: 4.2 | E24: 4.8 | F24: 4.3 | G24: 6 | H24: 4.3 | I24: 3.3 | J24: 4.8
A25: MARCELO | B25: MED/LAT | C25: lento | D25: 2.7 | E25: 1.8 | F25: 3.7 | G25: 2.2 | H25: 4.2 | I25: 1.4 | J25: 2.6 | K25: 3.3
A26: MARIAN | B26: DEL/MED | C26: lento | D26: 4.3 | E26: 1.8 | F26: 4.1 | G26: 2.2 | H26: 3.6 | I26: 2.8 | J26: 3.3 | K26: 3.9
A27: MATI BRAIAN | B27: DEF/MED | C27: rapido | D27: 3.6 | E27: 3.3 | F27: 3.9 | G27: 4.8 | H27: 2.6 | I27: 2.8 | J27: 3.3 | K27: 3.4
A28: MATI ROSALES | B28: MED/LAT | C28: rapido | D28: 3.9 | E28: 4.1 | F28: 6 | G28: 3.6 | H28: 5.4 | I28: 3.9 | J28: 4.3
A29: MAURI | B29: DEL | C29: rapido | D29: 3.9 | E29: 2.6 | F29: 3.3 | G29: 4 | H29: 3.3 | I29: 3.9 | J29: 3.6 | K29: 3.3
A30: MAXI | B30: MED | C30: lento | D30: 2.8 | E30: 1.8 | F30: 3.6 | G30: 2 | H30: 3 | I30: 2.8 | J30: 2.2 | K30: 2.5
A31: NICO | B31: MED/LAT | C31: rapido | D31: 3.9 | E31: 2.6 | F31: 3.9 | G31: 3.3 | H31: 3.9 | I31: 3.3 | J31: 3.3 | K31: 3.3
A32: PABLO | B32: DEF/LAT | C32: rapido | D32: 3 | E32: 5 | F32: 3.9 | G32: 3.9 | H32: 3.9 | I32: 5.4 | J32: 5.4
A33: PABLO CASTILLO | B33: LAT/MED | C33: lento | D33: 3 | E33: 3.9 | F33: 3.9 | G33: 3 | H33: 4.3 | I33: 3.6 | J33: 3 | K33: 3.3
A34: PABLO GARCIA | B34: MED/LAT | C34: rapido | D34: 2.3 | E34: 3 | F34: 2.7 | G34: 3.3 | H34: 3.3 | I34: 4.3 | J34: 3.9 | K34: 3.3
A35: PELA | B35: DEL/MED | C35: rapido | D35: 4.3 | E35: 3.6 | F35: 4.3 | G35: 3.6 | H35: 2.8 | I35: 4.3 | J35: 2.2 | K35: 3.6
A36: PULY | B36: DEL/MED | C36: lento | D36: 3 | E36: 1 | F36: 5 | G36: 2.2 | H36: 3 | I36: 2.2 | J36: 2.2 | K36: 3.3
A37: RODRI CHAVEZ | B37: LAT/MED | C37: rapido | D37: 3.6 | E37: 4.1 | F37: 3.9 | G37: 4.3 | H37: 4.3 | I37: 4.8 | J37: 4.8 | K37: 3.6
A38: RODRI SUAREZ | B38: DEF/ARQ | C38: lento | D38: 2.2 | E38: 3.7 | F38: 2.8 | G38: 3 | H38: 3.6 | I38: 3.9 | J38: 3.9 | K38: 3.9
A39: SANTI | B39: ARQ/MED | C39: rapido | D39: 3 | E39: 3 | F39: 5 | G39: 4 | H39: 3 | I39: 3 | J39: 4 | K39: 3.3
A40: SEBACORTEZ | B40: DEF/ARQ | C40: lento | D40: 3.3 | E40: 4.1 | F40: 3.9 | G40: 2.8 | H40: 3.6 | I40: 4.3 | J40: 3 | K40: 4.8
...

Sheet Directivo 4
A1: Nombre jugador | B1: Posiciones | C1: Ritmo base | D1: Ataque | E1: Solidez | F1: Tecnica | G1: Ritmo | H1: Equipo | I1: Mentalidad | J1: Regularidad | K1: Arquero | L1: Comentarios
A2: ALE CUERVO | B2: LAT/MED | C2: lento | D2: 2.8 | E2: 2.6 | F2: 3.3 | G2: 3 | H2: 3 | I2: 2.2 | J2: 2.8 | K2: 3.6
A3: ALEXIS | B3: LAT/MED | C3: rapido | D3: 3.6 | E3: 3.6 | F3: 3.9 | G3: 4.8 | H3: 3.3 | I3: 4.3 | J3: 4.8 | K3: 3.3
A4: ANIBAL | B4: DEL | C4: lento | D4: 3.7 | E4: 1.8 | F4: 3.6 | G4: 1.4 | H4: 1.8 | I4: 2.2 | J4: 2.8 | K4: 4.3
A5: AUGUSTO | B5: MED/LAT | C5: rapido | D5: 3.7 | E5: 3.3 | F5: 4.3 | G5: 4.3 | H5: 3.9 | I5: 2.8 | J5: 2.6 | K5: 3.6
A6: BETO | B6: DEL/MED | C6: lento | D6: 3.7 | E6: 1.8 | F6: 3.6 | G6: 2.2 | H6: 3 | I6: 3.6 | J6: 4 | K6: 3.3
A7: BRIAN | B7: DEL/MED | C7: rapido | D7: 5.4 | E7: 3.9 | F7: 5.4 | G7: 3.9 | H7: 4.3 | I7: 2.8 | J7: 4.8
A8: CAMILO | B8: MED/DEL | C8: rapido | D8: 3.9 | E8: 3 | F8: 5 | G8: 4.3 | H8: 4 | I8: 4 | J8: 4 | K8: 3.3
A9: CESAR | B9: DEF/LAT | C9: rapido | D9: 3.6 | E9: 4.6 | F9: 4.3 | G9: 3.3 | H9: 4.1 | I9: 3.6 | J9: 4.8
A10: COMANCHE | B10: LAT/MED | C10: lento | D10: 2.8 | E10: 2.7 | F10: 3.6 | G10: 2 | H10: 1.8 | I10: 3 | J10: 3 | K10: 3.9
A11: CRISTIAN | B11: DEL/ARQ | C11: lento | D11: 2.6 | E11: 1.4 | F11: 2.8 | G11: 2.2 | H11: 2.8 | I11: 3.9 | J11: 2.8 | K11: 3.6
A12: CUERVO | B12: DEL/DEF | C12: rapido | D12: 6 | E12: 3.6 | F12: 5.4 | G12: 3.6 | H12: 2.8 | I12: 3.3 | J12: 2.8
A13: ELIAN | B13: DEF/DEL | C13: lento | D13: 2.2 | E13: 1.4 | F13: 2.9 | G13: 1.4 | H13: 2.8 | I13: 2.8 | J13: 2 | K13: 3.3
A14: FACU | B14: DEF/DEL | C14: lento | D14: 2.6 | E14: 4.1 | F14: 2.9 | G14: 2.8 | H14: 3 | I14: 2.6 | J14: 3.9 | K14: 2.8
A15: FRANCISCO | B15: ARQ/DEL | C15: lento | D15: 1.4 | E15: 2.2 | F15: 1.4 | G15: 3 | H15: 2.2 | I15: 3.6 | J15: 2.8 | K15: 3.6
A16: FRANCO COMOLLI | B16: MED/DEL | C16: rapido | D16: 4.3 | E16: 4.3 | F16: 5 | G16: 4.8 | H16: 4.8 | I16: 4.8 | J16: 5.4 | K16: 3.3
A17: FRANCOK | B17: ARQ/LAT | C17: rapido | D17: 1.4 | E17: 2.8 | F17: 2.6 | G17: 3.6 | H17: 3 | I17: 3 | J17: 3.3 | K17: 3.9
A18: FRANQUITO | B18: MED | C18: rapido | D18: 3.4 | E18: 3 | F18: 3.9 | G18: 4.3 | H18: 3.3 | I18: 3.3 | J18: 4 | K18: 3.6
A19: GONZA | B19: ARQ/DEF | C19: lento | D19: 2.6 | E19: 3.9 | F19: 3 | G19: 3 | H19: 3.3 | I19: 3.3 | J19: 3.9 | K19: 3.9
A20: GUILLE | B20: LAT/ARQ | C20: lento | D20: 2.2 | E20: 1.4 | F20: 2.6 | G20: 1.4 | H20: 2.8 | I20: 3.9 | J20: 2.8 | K20: 3.3
A21: ISMA | B21: MED/LAT | C21: rapido | D21: 3.6 | E21: 3.9 | F21: 4.8 | G21: 3.9 | H21: 4.6 | I21: 4.3 | J21: 4.3 | K21: 3.6
A22: JAVI | B22: DEF/ARQ | C22: lento | D22: 2.8 | E22: 3.7 | F22: 3.2 | G22: 3 | H22: 3.3 | I22: 3.9 | J22: 3 | K22: 4.8
A23: JEAN FRANCO | B23: DEL | C23: lento | D23: 2 | E23: 2 | F23: 3 | G23: 3 | H23: 3 | I23: 4 | J23: 2.2 | K23: 2.6
A24: MANU | B24: LAT/MED | C24: rapido | D24: 4.2 | E24: 4.8 | F24: 4.3 | G24: 6 | H24: 4.3 | I24: 3.3 | J24: 4.8
A25: MARCELO | B25: MED/LAT | C25: lento | D25: 2.7 | E25: 1.8 | F25: 3.7 | G25: 2.2 | H25: 4.2 | I25: 1.4 | J25: 2.6 | K25: 3.3
A26: MARIAN | B26: DEL/MED | C26: lento | D26: 4.3 | E26: 1.8 | F26: 4.1 | G26: 2.2 | H26: 3.6 | I26: 2.8 | J26: 3.3 | K26: 3.9
A27: MATI BRAIAN | B27: DEF/MED | C27: rapido | D27: 3.6 | E27: 3.3 | F27: 3.9 | G27: 4.8 | H27: 2.6 | I27: 2.8 | J27: 3.3 | K27: 3.4
A28: MATI ROSALES | B28: MED/LAT | C28: rapido | D28: 3.9 | E28: 4.1 | F28: 6 | G28: 3.6 | H28: 5.4 | I28: 3.9 | J28: 4.3
A29: MAURI | B29: DEL | C29: rapido | D29: 3.9 | E29: 2.6 | F29: 3.3 | G29: 4 | H29: 3.3 | I29: 3.9 | J29: 3.6 | K29: 3.3
A30: MAXI | B30: MED | C30: lento | D30: 2.8 | E30: 1.8 | F30: 3.6 | G30: 2 | H30: 3 | I30: 2.8 | J30: 2.2 | K30: 2.5
A31: NICO | B31: MED/LAT | C31: rapido | D31: 3.9 | E31: 2.6 | F31: 3.9 | G31: 3.3 | H31: 3.9 | I31: 3.3 | J31: 3.3 | K31: 3.3
A32: PABLO | B32: DEF/LAT | C32: rapido | D32: 3 | E32: 5 | F32: 3.9 | G32: 3.9 | H32: 3.9 | I32: 5.4 | J32: 5.4
A33: PABLO CASTILLO | B33: LAT/MED | C33: lento | D33: 3 | E33: 3.9 | F33: 3.9 | G33: 3 | H33: 4.3 | I33: 3.6 | J33: 3 | K33: 3.3
A34: PABLO GARCIA | B34: MED/LAT | C34: rapido | D34: 2.3 | E34: 3 | F34: 2.7 | G34: 3.3 | H34: 3.3 | I34: 4.3 | J34: 3.9 | K34: 3.3
A35: PELA | B35: DEL/MED | C35: rapido | D35: 4.3 | E35: 3.6 | F35: 4.3 | G35: 3.6 | H35: 2.8 | I35: 4.3 | J35: 2.2 | K35: 3.6
A36: PULY | B36: DEL/MED | C36: lento | D36: 3 | E36: 1 | F36: 5 | G36: 2.2 | H36: 3 | I36: 2.2 | J36: 2.2 | K36: 3.3
A37: RODRI CHAVEZ | B37: LAT/MED | C37: rapido | D37: 3.6 | E37: 4.1 | F37: 3.9 | G37: 4.3 | H37: 4.3 | I37: 4.8 | J37: 4.8 | K37: 3.6
A38: RODRI SUAREZ | B38: DEF/ARQ | C38: lento | D38: 2.2 | E38: 3.7 | F38: 2.8 | G38: 3 | H38: 3.6 | I38: 3.9 | J38: 3.9 | K38: 3.9
A39: SANTI | B39: ARQ/MED | C39: rapido | D39: 3 | E39: 3 | F39: 5 | G39: 4 | H39: 3 | I39: 3 | J39: 4 | K39: 3.3
A40: SEBACORTEZ | B40: DEF/ARQ | C40: lento | D40: 3.3 | E40: 4.1 | F40: 3.9 | G40: 2.8 | H40: 3.6 | I40: 4.3 | J40: 3 | K40: 4.8
...

Sheet Directivo 5
A1: Nombre jugador | B1: Posiciones | C1: Ritmo base | D1: Ataque | E1: Solidez | F1: Tecnica | G1: Ritmo | H1: Equipo | I1: Mentalidad | J1: Regularidad | K1: Arquero | L1: Comentarios
A2: ALE CUERVO | B2: LAT/MED | C2: lento | D2: 2.8 | E2: 2.6 | F2: 3.3 | G2: 3 | H2: 3 | I2: 2.2 | J2: 2.8 | K2: 3.6
A3: ALEXIS | B3: LAT/MED | C3: rapido | D3: 3.6 | E3: 3.6 | F3: 3.9 | G3: 4.8 | H3: 3.3 | I3: 4.3 | J3: 4.8 | K3: 3.3
A4: ANIBAL | B4: DEL | C4: lento | D4: 3.7 | E4: 1.8 | F4: 3.6 | G4: 1.4 | H4: 1.8 | I4: 2.2 | J4: 2.8 | K4: 4.3
A5: AUGUSTO | B5: MED/LAT | C5: rapido | D5: 3.7 | E5: 3.3 | F5: 4.3 | G5: 4.3 | H5: 3.9 | I5: 2.8 | J5: 2.6 | K5: 3.6
A6: BETO | B6: DEL/MED | C6: lento | D6: 3.7 | E6: 1.8 | F6: 3.6 | G6: 2.2 | H6: 3 | I6: 3.6 | J6: 4 | K6: 3.3
A7: BRIAN | B7: DEL/MED | C7: rapido | D7: 5.4 | E7: 3.9 | F7: 5.4 | G7: 3.9 | H7: 4.3 | I7: 2.8 | J7: 4.8
A8: CAMILO | B8: MED/DEL | C8: rapido | D8: 3.9 | E8: 3 | F8: 5 | G8: 4.3 | H8: 4 | I8: 4 | J8: 4 | K8: 3.3
A9: CESAR | B9: DEF/LAT | C9: rapido | D9: 3.6 | E9: 4.6 | F9: 4.3 | G9: 3.3 | H9: 4.1 | I9: 3.6 | J9: 4.8
A10: COMANCHE | B10: LAT/MED | C10: lento | D10: 2.8 | E10: 2.7 | F10: 3.6 | G10: 2 | H10: 1.8 | I10: 3 | J10: 3 | K10: 3.9
A11: CRISTIAN | B11: DEL/ARQ | C11: lento | D11: 2.6 | E11: 1.4 | F11: 2.8 | G11: 2.2 | H11: 2.8 | I11: 3.9 | J11: 2.8 | K11: 3.6
A12: CUERVO | B12: DEL/DEF | C12: rapido | D12: 6 | E12: 3.6 | F12: 5.4 | G12: 3.6 | H12: 2.8 | I12: 3.3 | J12: 2.8
A13: ELIAN | B13: DEF/DEL | C13: lento | D13: 2.2 | E13: 1.4 | F13: 2.9 | G13: 1.4 | H13: 2.8 | I13: 2.8 | J13: 2 | K13: 3.3
A14: FACU | B14: DEF/DEL | C14: lento | D14: 2.6 | E14: 4.1 | F14: 2.9 | G14: 2.8 | H14: 3 | I14: 2.6 | J14: 3.9 | K14: 2.8
A15: FRANCISCO | B15: ARQ/DEL | C15: lento | D15: 1.4 | E15: 2.2 | F15: 1.4 | G15: 3 | H15: 2.2 | I15: 3.6 | J15: 2.8 | K15: 3.6
A16: FRANCO COMOLLI | B16: MED/DEL | C16: rapido | D16: 4.3 | E16: 4.3 | F16: 5 | G16: 4.8 | H16: 4.8 | I16: 4.8 | J16: 5.4 | K16: 3.3
A17: FRANCOK | B17: ARQ/LAT | C17: rapido | D17: 1.4 | E17: 2.8 | F17: 2.6 | G17: 3.6 | H17: 3 | I17: 3 | J17: 3.3 | K17: 3.9
A18: FRANQUITO | B18: MED | C18: rapido | D18: 3.4 | E18: 3 | F18: 3.9 | G18: 4.3 | H18: 3.3 | I18: 3.3 | J18: 4 | K18: 3.6
A19: GONZA | B19: ARQ/DEF | C19: lento | D19: 2.6 | E19: 3.9 | F19: 3 | G19: 3 | H19: 3.3 | I19: 3.3 | J19: 3.9 | K19: 3.9
A20: GUILLE | B20: LAT/ARQ | C20: lento | D20: 2.2 | E20: 1.4 | F20: 2.6 | G20: 1.4 | H20: 2.8 | I20: 3.9 | J20: 2.8 | K20: 3.3
A21: ISMA | B21: MED/LAT | C21: rapido | D21: 3.6 | E21: 3.9 | F21: 4.8 | G21: 3.9 | H21: 4.6 | I21: 4.3 | J21: 4.3 | K21: 3.6
A22: JAVI | B22: DEF/ARQ | C22: lento | D22: 2.8 | E22: 3.7 | F22: 3.2 | G22: 3 | H22: 3.3 | I22: 3.9 | J22: 3 | K22: 4.8
A23: JEAN FRANCO | B23: DEL | C23: lento | D23: 2 | E23: 2 | F23: 3 | G23: 3 | H23: 3 | I23: 4 | J23: 2.2 | K23: 2.6
A24: MANU | B24: LAT/MED | C24: rapido | D24: 4.2 | E24: 4.8 | F24: 4.3 | G24: 6 | H24: 4.3 | I24: 3.3 | J24: 4.8
A25: MARCELO | B25: MED/LAT | C25: lento | D25: 2.7 | E25: 1.8 | F25: 3.7 | G25: 2.2 | H25: 4.2 | I25: 1.4 | J25: 2.6 | K25: 3.3
A26: MARIAN | B26: DEL/MED | C26: lento | D26: 4.3 | E26: 1.8 | F26: 4.1 | G26: 2.2 | H26: 3.6 | I26: 2.8 | J26: 3.3 | K26: 3.9
A27: MATI BRAIAN | B27: DEF/MED | C27: rapido | D27: 3.6 | E27: 3.3 | F27: 3.9 | G27: 4.8 | H27: 2.6 | I27: 2.8 | J27: 3.3 | K27: 3.4
A28: MATI ROSALES | B28: MED/LAT | C28: rapido | D28: 3.9 | E28: 4.1 | F28: 6 | G28: 3.6 | H28: 5.4 | I28: 3.9 | J28: 4.3
A29: MAURI | B29: DEL | C29: rapido | D29: 3.9 | E29: 2.6 | F29: 3.3 | G29: 4 | H29: 3.3 | I29: 3.9 | J29: 3.6 | K29: 3.3
A30: MAXI | B30: MED | C30: lento | D30: 2.8 | E30: 1.8 | F30: 3.6 | G30: 2 | H30: 3 | I30: 2.8 | J30: 2.2 | K30: 2.5
A31: NICO | B31: MED/LAT | C31: rapido | D31: 3.9 | E31: 2.6 | F31: 3.9 | G31: 3.3 | H31: 3.9 | I31: 3.3 | J31: 3.3 | K31: 3.3
A32: PABLO | B32: DEF/LAT | C32: rapido | D32: 3 | E32: 5 | F32: 3.9 | G32: 3.9 | H32: 3.9 | I32: 5.4 | J32: 5.4
A33: PABLO CASTILLO | B33: LAT/MED | C33: lento | D33: 3 | E33: 3.9 | F33: 3.9 | G33: 3 | H33: 4.3 | I33: 3.6 | J33: 3 | K33: 3.3
A34: PABLO GARCIA | B34: MED/LAT | C34: rapido | D34: 2.3 | E34: 3 | F34: 2.7 | G34: 3.3 | H34: 3.3 | I34: 4.3 | J34: 3.9 | K34: 3.3
A35: PELA | B35: DEL/MED | C35: rapido | D35: 4.3 | E35: 3.6 | F35: 4.3 | G35: 3.6 | H35: 2.8 | I35: 4.3 | J35: 2.2 | K35: 3.6
A36: PULY | B36: DEL/MED | C36: lento | D36: 3 | E36: 1 | F36: 5 | G36: 2.2 | H36: 3 | I36: 2.2 | J36: 2.2 | K36: 3.3
A37: RODRI CHAVEZ | B37: LAT/MED | C37: rapido | D37: 3.6 | E37: 4.1 | F37: 3.9 | G37: 4.3 | H37: 4.3 | I37: 4.8 | J37: 4.8 | K37: 3.6
A38: RODRI SUAREZ | B38: DEF/ARQ | C38: lento | D38: 2.2 | E38: 3.7 | F38: 2.8 | G38: 3 | H38: 3.6 | I38: 3.9 | J38: 3.9 | K38: 3.9
A39: SANTI | B39: ARQ/MED | C39: rapido | D39: 3 | E39: 3 | F39: 5 | G39: 4 | H39: 3 | I39: 3 | J39: 4 | K39: 3.3
A40: SEBACORTEZ | B40: DEF/ARQ | C40: lento | D40: 3.3 | E40: 4.1 | F40: 3.9 | G40: 2.8 | H40: 3.6 | I40: 4.3 | J40: 3 | K40: 4.8
...

Sheet Instrucciones
A1: Planilla de carga de stats - Goodfellas
A2: Uso recomendado
A3: Subir este archivo a Google Drive y abrirlo con Google Sheets. Compartir el MISMO archivo con los 5 directivos con permiso de editor.
A4: Cada directivo debe completar solamente su pesta?a: Directivo 1, Directivo 2, etc.
A5: La pesta?a Consolidado promedia automaticamente los valores numericos de los 5 directivos.
A6: Escala sugerida: 1 a 6, usando decimales si hace falta.
A7: Columnas: Ataque, Solidez, Tecnica, Ritmo, Equipo, Mentalidad, Regularidad, Arquero.
A8: Comentarios es libre para dudas o ajustes puntuales.
