Workbook

Sheet Consolidado
A1: Nombre jugador | B1: Posiciones | C1: Ritmo base | D1: Ataque | E1: Solidez | F1: Tecnica | G1: Ritmo | H1: Equipo | I1: Mentalidad | J1: Regularidad | K1: Arquero | L1: Comentarios
A2: ALE CUERVO | B2: LAT/MED | C2: lento | D2: =IFERROR(ROUND(AVERAGE('Marcelo'!D2,'Braian'!D2,'Cesar'!D2,'Marian'!D2,'Guille'!D2,'Pela'!D2,'Rodri'!D2,'Pablo'!D2),0),"") | E2: =IFERROR(ROUND(AVERAGE('Marcelo'!E2,'Braian'!E2,'Cesar'!E2,'Marian'!E2,'Guille'!E2,'Pela'!E2,'Rodri'!E2,'Pablo'!E2),0),"") | F2: =IFERROR(ROUND(AVERAGE('Marcelo'!F2,'Braian'!F2,'Cesar'!F2,'Marian'!F2,'Guille'!F2,'Pela'!F2,'Rodri'!F2,'Pablo'!F2),0),"") | G2: =IFERROR(ROUND(AVERAGE('Marcelo'!G2,'Braian'!G2,'Cesar'!G2,'Marian'!G2,'Guille'!G2,'Pela'!G2,'Rodri'!G2,'Pablo'!G2),0),"") | H2: =IFERROR(ROUND(AVERAGE('Marcelo'!H2,'Braian'!H2,'Cesar'!H2,'Marian'!H2,'Guille'!H2,'Pela'!H2,'Rodri'!H2,'Pablo'!H2),0),"") | I2: =IFERROR(ROUND(AVERAGE('Marcelo'!I2,'Braian'!I2,'Cesar'!I2,'Marian'!I2,'Guille'!I2,'Pela'!I2,'Rodri'!I2,'Pablo'!I2),0),"") | J2: =IFERROR(ROUND(AVERAGE('Marcelo'!J2,'Braian'!J2,'Cesar'!J2,'Marian'!J2,'Guille'!J2,'Pela'!J2,'Rodri'!J2,'Pablo'!J2),0),"") | K2: =IFERROR(ROUND(AVERAGE('Marcelo'!K2,'Braian'!K2,'Cesar'!K2,'Marian'!K2,'Guille'!K2,'Pela'!K2,'Rodri'!K2,'Pablo'!K2),0),"") | L2: =TEXTJOIN(" | ",TRUE,'Marcelo'!L2,'Braian'!L2,'Cesar'!L2,'Marian'!L2,'Guille'!L2,'Pela'!L2,'Rodri'!L2,'Pablo'!L2)
A3: ALEXIS | B3: LAT/MED | C3: rapido | D3: =IFERROR(ROUND(AVERAGE('Marcelo'!D3,'Braian'!D3,'Cesar'!D3,'Marian'!D3,'Guille'!D3,'Pela'!D3,'Rodri'!D3,'Pablo'!D3),0),"") | E3: =IFERROR(ROUND(AVERAGE('Marcelo'!E3,'Braian'!E3,'Cesar'!E3,'Marian'!E3,'Guille'!E3,'Pela'!E3,'Rodri'!E3,'Pablo'!E3),0),"") | F3: =IFERROR(ROUND(AVERAGE('Marcelo'!F3,'Braian'!F3,'Cesar'!F3,'Marian'!F3,'Guille'!F3,'Pela'!F3,'Rodri'!F3,'Pablo'!F3),0),"") | G3: =IFERROR(ROUND(AVERAGE('Marcelo'!G3,'Braian'!G3,'Cesar'!G3,'Marian'!G3,'Guille'!G3,'Pela'!G3,'Rodri'!G3,'Pablo'!G3),0),"") | H3: =IFERROR(ROUND(AVERAGE('Marcelo'!H3,'Braian'!H3,'Cesar'!H3,'Marian'!H3,'Guille'!H3,'Pela'!H3,'Rodri'!H3,'Pablo'!H3),0),"") | I3: =IFERROR(ROUND(AVERAGE('Marcelo'!I3,'Braian'!I3,'Cesar'!I3,'Marian'!I3,'Guille'!I3,'Pela'!I3,'Rodri'!I3,'Pablo'!I3),0),"") | J3: =IFERROR(ROUND(AVERAGE('Marcelo'!J3,'Braian'!J3,'Cesar'!J3,'Marian'!J3,'Guille'!J3,'Pela'!J3,'Rodri'!J3,'Pablo'!J3),0),"") | K3: =IFERROR(ROUND(AVERAGE('Marcelo'!K3,'Braian'!K3,'Cesar'!K3,'Marian'!K3,'Guille'!K3,'Pela'!K3,'Rodri'!K3,'Pablo'!K3),0),"") | L3: =TEXTJOIN(" | ",TRUE,'Marcelo'!L3,'Braian'!L3,'Cesar'!L3,'Marian'!L3,'Guille'!L3,'Pela'!L3,'Rodri'!L3,'Pablo'!L3)
A4: ANIBAL | B4: DEL | C4: lento | D4: =IFERROR(ROUND(AVERAGE('Marcelo'!D4,'Braian'!D4,'Cesar'!D4,'Marian'!D4,'Guille'!D4,'Pela'!D4,'Rodri'!D4,'Pablo'!D4),0),"") | E4: =IFERROR(ROUND(AVERAGE('Marcelo'!E4,'Braian'!E4,'Cesar'!E4,'Marian'!E4,'Guille'!E4,'Pela'!E4,'Rodri'!E4,'Pablo'!E4),0),"") | F4: =IFERROR(ROUND(AVERAGE('Marcelo'!F4,'Braian'!F4,'Cesar'!F4,'Marian'!F4,'Guille'!F4,'Pela'!F4,'Rodri'!F4,'Pablo'!F4),0),"") | G4: =IFERROR(ROUND(AVERAGE('Marcelo'!G4,'Braian'!G4,'Cesar'!G4,'Marian'!G4,'Guille'!G4,'Pela'!G4,'Rodri'!G4,'Pablo'!G4),0),"") | H4: =IFERROR(ROUND(AVERAGE('Marcelo'!H4,'Braian'!H4,'Cesar'!H4,'Marian'!H4,'Guille'!H4,'Pela'!H4,'Rodri'!H4,'Pablo'!H4),0),"") | I4: =IFERROR(ROUND(AVERAGE('Marcelo'!I4,'Braian'!I4,'Cesar'!I4,'Marian'!I4,'Guille'!I4,'Pela'!I4,'Rodri'!I4,'Pablo'!I4),0),"") | J4: =IFERROR(ROUND(AVERAGE('Marcelo'!J4,'Braian'!J4,'Cesar'!J4,'Marian'!J4,'Guille'!J4,'Pela'!J4,'Rodri'!J4,'Pablo'!J4),0),"") | K4: =IFERROR(ROUND(AVERAGE('Marcelo'!K4,'Braian'!K4,'Cesar'!K4,'Marian'!K4,'Guille'!K4,'Pela'!K4,'Rodri'!K4,'Pablo'!K4),0),"") | L4: =TEXTJOIN(" | ",TRUE,'Marcelo'!L4,'Braian'!L4,'Cesar'!L4,'Marian'!L4,'Guille'!L4,'Pela'!L4,'Rodri'!L4,'Pablo'!L4)
A5: AUGUSTO | B5: MED/LAT | C5: rapido | D5: =IFERROR(ROUND(AVERAGE('Marcelo'!D5,'Braian'!D5,'Cesar'!D5,'Marian'!D5,'Guille'!D5,'Pela'!D5,'Rodri'!D5,'Pablo'!D5),0),"") | E5: =IFERROR(ROUND(AVERAGE('Marcelo'!E5,'Braian'!E5,'Cesar'!E5,'Marian'!E5,'Guille'!E5,'Pela'!E5,'Rodri'!E5,'Pablo'!E5),0),"") | F5: =IFERROR(ROUND(AVERAGE('Marcelo'!F5,'Braian'!F5,'Cesar'!F5,'Marian'!F5,'Guille'!F5,'Pela'!F5,'Rodri'!F5,'Pablo'!F5),0),"") | G5: =IFERROR(ROUND(AVERAGE('Marcelo'!G5,'Braian'!G5,'Cesar'!G5,'Marian'!G5,'Guille'!G5,'Pela'!G5,'Rodri'!G5,'Pablo'!G5),0),"") | H5: =IFERROR(ROUND(AVERAGE('Marcelo'!H5,'Braian'!H5,'Cesar'!H5,'Marian'!H5,'Guille'!H5,'Pela'!H5,'Rodri'!H5,'Pablo'!H5),0),"") | I5: =IFERROR(ROUND(AVERAGE('Marcelo'!I5,'Braian'!I5,'Cesar'!I5,'Marian'!I5,'Guille'!I5,'Pela'!I5,'Rodri'!I5,'Pablo'!I5),0),"") | J5: =IFERROR(ROUND(AVERAGE('Marcelo'!J5,'Braian'!J5,'Cesar'!J5,'Marian'!J5,'Guille'!J5,'Pela'!J5,'Rodri'!J5,'Pablo'!J5),0),"") | K5: =IFERROR(ROUND(AVERAGE('Marcelo'!K5,'Braian'!K5,'Cesar'!K5,'Marian'!K5,'Guille'!K5,'Pela'!K5,'Rodri'!K5,'Pablo'!K5),0),"") | L5: =TEXTJOIN(" | ",TRUE,'Marcelo'!L5,'Braian'!L5,'Cesar'!L5,'Marian'!L5,'Guille'!L5,'Pela'!L5,'Rodri'!L5,'Pablo'!L5)
A6: BETO | B6: DEL/MED | C6: lento | D6: =IFERROR(ROUND(AVERAGE('Marcelo'!D6,'Braian'!D6,'Cesar'!D6,'Marian'!D6,'Guille'!D6,'Pela'!D6,'Rodri'!D6,'Pablo'!D6),0),"") | E6: =IFERROR(ROUND(AVERAGE('Marcelo'!E6,'Braian'!E6,'Cesar'!E6,'Marian'!E6,'Guille'!E6,'Pela'!E6,'Rodri'!E6,'Pablo'!E6),0),"") | F6: =IFERROR(ROUND(AVERAGE('Marcelo'!F6,'Braian'!F6,'Cesar'!F6,'Marian'!F6,'Guille'!F6,'Pela'!F6,'Rodri'!F6,'Pablo'!F6),0),"") | G6: =IFERROR(ROUND(AVERAGE('Marcelo'!G6,'Braian'!G6,'Cesar'!G6,'Marian'!G6,'Guille'!G6,'Pela'!G6,'Rodri'!G6,'Pablo'!G6),0),"") | H6: =IFERROR(ROUND(AVERAGE('Marcelo'!H6,'Braian'!H6,'Cesar'!H6,'Marian'!H6,'Guille'!H6,'Pela'!H6,'Rodri'!H6,'Pablo'!H6),0),"") | I6: =IFERROR(ROUND(AVERAGE('Marcelo'!I6,'Braian'!I6,'Cesar'!I6,'Marian'!I6,'Guille'!I6,'Pela'!I6,'Rodri'!I6,'Pablo'!I6),0),"") | J6: =IFERROR(ROUND(AVERAGE('Marcelo'!J6,'Braian'!J6,'Cesar'!J6,'Marian'!J6,'Guille'!J6,'Pela'!J6,'Rodri'!J6,'Pablo'!J6),0),"") | K6: =IFERROR(ROUND(AVERAGE('Marcelo'!K6,'Braian'!K6,'Cesar'!K6,'Marian'!K6,'Guille'!K6,'Pela'!K6,'Rodri'!K6,'Pablo'!K6),0),"") | L6: =TEXTJOIN(" | ",TRUE,'Marcelo'!L6,'Braian'!L6,'Cesar'!L6,'Marian'!L6,'Guille'!L6,'Pela'!L6,'Rodri'!L6,'Pablo'!L6)
A7: BRIAN | B7: DEL/MED | C7: rapido | D7: =IFERROR(ROUND(AVERAGE('Marcelo'!D7,'Braian'!D7,'Cesar'!D7,'Marian'!D7,'Guille'!D7,'Pela'!D7,'Rodri'!D7,'Pablo'!D7),0),"") | E7: =IFERROR(ROUND(AVERAGE('Marcelo'!E7,'Braian'!E7,'Cesar'!E7,'Marian'!E7,'Guille'!E7,'Pela'!E7,'Rodri'!E7,'Pablo'!E7),0),"") | F7: =IFERROR(ROUND(AVERAGE('Marcelo'!F7,'Braian'!F7,'Cesar'!F7,'Marian'!F7,'Guille'!F7,'Pela'!F7,'Rodri'!F7,'Pablo'!F7),0),"") | G7: =IFERROR(ROUND(AVERAGE('Marcelo'!G7,'Braian'!G7,'Cesar'!G7,'Marian'!G7,'Guille'!G7,'Pela'!G7,'Rodri'!G7,'Pablo'!G7),0),"") | H7: =IFERROR(ROUND(AVERAGE('Marcelo'!H7,'Braian'!H7,'Cesar'!H7,'Marian'!H7,'Guille'!H7,'Pela'!H7,'Rodri'!H7,'Pablo'!H7),0),"") | I7: =IFERROR(ROUND(AVERAGE('Marcelo'!I7,'Braian'!I7,'Cesar'!I7,'Marian'!I7,'Guille'!I7,'Pela'!I7,'Rodri'!I7,'Pablo'!I7),0),"") | J7: =IFERROR(ROUND(AVERAGE('Marcelo'!J7,'Braian'!J7,'Cesar'!J7,'Marian'!J7,'Guille'!J7,'Pela'!J7,'Rodri'!J7,'Pablo'!J7),0),"") | K7: =IFERROR(ROUND(AVERAGE('Marcelo'!K7,'Braian'!K7,'Cesar'!K7,'Marian'!K7,'Guille'!K7,'Pela'!K7,'Rodri'!K7,'Pablo'!K7),0),"") | L7: =TEXTJOIN(" | ",TRUE,'Marcelo'!L7,'Braian'!L7,'Cesar'!L7,'Marian'!L7,'Guille'!L7,'Pela'!L7,'Rodri'!L7,'Pablo'!L7)
A8: CAMILO | B8: MED/DEL | C8: rapido | D8: =IFERROR(ROUND(AVERAGE('Marcelo'!D8,'Braian'!D8,'Cesar'!D8,'Marian'!D8,'Guille'!D8,'Pela'!D8,'Rodri'!D8,'Pablo'!D8),0),"") | E8: =IFERROR(ROUND(AVERAGE('Marcelo'!E8,'Braian'!E8,'Cesar'!E8,'Marian'!E8,'Guille'!E8,'Pela'!E8,'Rodri'!E8,'Pablo'!E8),0),"") | F8: =IFERROR(ROUND(AVERAGE('Marcelo'!F8,'Braian'!F8,'Cesar'!F8,'Marian'!F8,'Guille'!F8,'Pela'!F8,'Rodri'!F8,'Pablo'!F8),0),"") | G8: =IFERROR(ROUND(AVERAGE('Marcelo'!G8,'Braian'!G8,'Cesar'!G8,'Marian'!G8,'Guille'!G8,'Pela'!G8,'Rodri'!G8,'Pablo'!G8),0),"") | H8: =IFERROR(ROUND(AVERAGE('Marcelo'!H8,'Braian'!H8,'Cesar'!H8,'Marian'!H8,'Guille'!H8,'Pela'!H8,'Rodri'!H8,'Pablo'!H8),0),"") | I8: =IFERROR(ROUND(AVERAGE('Marcelo'!I8,'Braian'!I8,'Cesar'!I8,'Marian'!I8,'Guille'!I8,'Pela'!I8,'Rodri'!I8,'Pablo'!I8),0),"") | J8: =IFERROR(ROUND(AVERAGE('Marcelo'!J8,'Braian'!J8,'Cesar'!J8,'Marian'!J8,'Guille'!J8,'Pela'!J8,'Rodri'!J8,'Pablo'!J8),0),"") | K8: =IFERROR(ROUND(AVERAGE('Marcelo'!K8,'Braian'!K8,'Cesar'!K8,'Marian'!K8,'Guille'!K8,'Pela'!K8,'Rodri'!K8,'Pablo'!K8),0),"") | L8: =TEXTJOIN(" | ",TRUE,'Marcelo'!L8,'Braian'!L8,'Cesar'!L8,'Marian'!L8,'Guille'!L8,'Pela'!L8,'Rodri'!L8,'Pablo'!L8)
A9: CESAR | B9: DEF/LAT | C9: rapido | D9: =IFERROR(ROUND(AVERAGE('Marcelo'!D9,'Braian'!D9,'Cesar'!D9,'Marian'!D9,'Guille'!D9,'Pela'!D9,'Rodri'!D9,'Pablo'!D9),0),"") | E9: =IFERROR(ROUND(AVERAGE('Marcelo'!E9,'Braian'!E9,'Cesar'!E9,'Marian'!E9,'Guille'!E9,'Pela'!E9,'Rodri'!E9,'Pablo'!E9),0),"") | F9: =IFERROR(ROUND(AVERAGE('Marcelo'!F9,'Braian'!F9,'Cesar'!F9,'Marian'!F9,'Guille'!F9,'Pela'!F9,'Rodri'!F9,'Pablo'!F9),0),"") | G9: =IFERROR(ROUND(AVERAGE('Marcelo'!G9,'Braian'!G9,'Cesar'!G9,'Marian'!G9,'Guille'!G9,'Pela'!G9,'Rodri'!G9,'Pablo'!G9),0),"") | H9: =IFERROR(ROUND(AVERAGE('Marcelo'!H9,'Braian'!H9,'Cesar'!H9,'Marian'!H9,'Guille'!H9,'Pela'!H9,'Rodri'!H9,'Pablo'!H9),0),"") | I9: =IFERROR(ROUND(AVERAGE('Marcelo'!I9,'Braian'!I9,'Cesar'!I9,'Marian'!I9,'Guille'!I9,'Pela'!I9,'Rodri'!I9,'Pablo'!I9),0),"") | J9: =IFERROR(ROUND(AVERAGE('Marcelo'!J9,'Braian'!J9,'Cesar'!J9,'Marian'!J9,'Guille'!J9,'Pela'!J9,'Rodri'!J9,'Pablo'!J9),0),"") | K9: =IFERROR(ROUND(AVERAGE('Marcelo'!K9,'Braian'!K9,'Cesar'!K9,'Marian'!K9,'Guille'!K9,'Pela'!K9,'Rodri'!K9,'Pablo'!K9),0),"") | L9: =TEXTJOIN(" | ",TRUE,'Marcelo'!L9,'Braian'!L9,'Cesar'!L9,'Marian'!L9,'Guille'!L9,'Pela'!L9,'Rodri'!L9,'Pablo'!L9)
A10: COMANCHE | B10: LAT/MED | C10: lento | D10: =IFERROR(ROUND(AVERAGE('Marcelo'!D10,'Braian'!D10,'Cesar'!D10,'Marian'!D10,'Guille'!D10,'Pela'!D10,'Rodri'!D10,'Pablo'!D10),0),"") | E10: =IFERROR(ROUND(AVERAGE('Marcelo'!E10,'Braian'!E10,'Cesar'!E10,'Marian'!E10,'Guille'!E10,'Pela'!E10,'Rodri'!E10,'Pablo'!E10),0),"") | F10: =IFERROR(ROUND(AVERAGE('Marcelo'!F10,'Braian'!F10,'Cesar'!F10,'Marian'!F10,'Guille'!F10,'Pela'!F10,'Rodri'!F10,'Pablo'!F10),0),"") | G10: =IFERROR(ROUND(AVERAGE('Marcelo'!G10,'Braian'!G10,'Cesar'!G10,'Marian'!G10,'Guille'!G10,'Pela'!G10,'Rodri'!G10,'Pablo'!G10),0),"") | H10: =IFERROR(ROUND(AVERAGE('Marcelo'!H10,'Braian'!H10,'Cesar'!H10,'Marian'!H10,'Guille'!H10,'Pela'!H10,'Rodri'!H10,'Pablo'!H10),0),"") | I10: =IFERROR(ROUND(AVERAGE('Marcelo'!I10,'Braian'!I10,'Cesar'!I10,'Marian'!I10,'Guille'!I10,'Pela'!I10,'Rodri'!I10,'Pablo'!I10),0),"") | J10: =IFERROR(ROUND(AVERAGE('Marcelo'!J10,'Braian'!J10,'Cesar'!J10,'Marian'!J10,'Guille'!J10,'Pela'!J10,'Rodri'!J10,'Pablo'!J10),0),"") | K10: =IFERROR(ROUND(AVERAGE('Marcelo'!K10,'Braian'!K10,'Cesar'!K10,'Marian'!K10,'Guille'!K10,'Pela'!K10,'Rodri'!K10,'Pablo'!K10),0),"") | L10: =TEXTJOIN(" | ",TRUE,'Marcelo'!L10,'Braian'!L10,'Cesar'!L10,'Marian'!L10,'Guille'!L10,'Pela'!L10,'Rodri'!L10,'Pablo'!L10)
A11: CRISTIAN | B11: DEL/ARQ | C11: lento | D11: =IFERROR(ROUND(AVERAGE('Marcelo'!D11,'Braian'!D11,'Cesar'!D11,'Marian'!D11,'Guille'!D11,'Pela'!D11,'Rodri'!D11,'Pablo'!D11),0),"") | E11: =IFERROR(ROUND(AVERAGE('Marcelo'!E11,'Braian'!E11,'Cesar'!E11,'Marian'!E11,'Guille'!E11,'Pela'!E11,'Rodri'!E11,'Pablo'!E11),0),"") | F11: =IFERROR(ROUND(AVERAGE('Marcelo'!F11,'Braian'!F11,'Cesar'!F11,'Marian'!F11,'Guille'!F11,'Pela'!F11,'Rodri'!F11,'Pablo'!F11),0),"") | G11: =IFERROR(ROUND(AVERAGE('Marcelo'!G11,'Braian'!G11,'Cesar'!G11,'Marian'!G11,'Guille'!G11,'Pela'!G11,'Rodri'!G11,'Pablo'!G11),0),"") | H11: =IFERROR(ROUND(AVERAGE('Marcelo'!H11,'Braian'!H11,'Cesar'!H11,'Marian'!H11,'Guille'!H11,'Pela'!H11,'Rodri'!H11,'Pablo'!H11),0),"") | I11: =IFERROR(ROUND(AVERAGE('Marcelo'!I11,'Braian'!I11,'Cesar'!I11,'Marian'!I11,'Guille'!I11,'Pela'!I11,'Rodri'!I11,'Pablo'!I11),0),"") | J11: =IFERROR(ROUND(AVERAGE('Marcelo'!J11,'Braian'!J11,'Cesar'!J11,'Marian'!J11,'Guille'!J11,'Pela'!J11,'Rodri'!J11,'Pablo'!J11),0),"") | K11: =IFERROR(ROUND(AVERAGE('Marcelo'!K11,'Braian'!K11,'Cesar'!K11,'Marian'!K11,'Guille'!K11,'Pela'!K11,'Rodri'!K11,'Pablo'!K11),0),"") | L11: =TEXTJOIN(" | ",TRUE,'Marcelo'!L11,'Braian'!L11,'Cesar'!L11,'Marian'!L11,'Guille'!L11,'Pela'!L11,'Rodri'!L11,'Pablo'!L11)
A12: CUERVO | B12: DEL/DEF | C12: rapido | D12: =IFERROR(ROUND(AVERAGE('Marcelo'!D12,'Braian'!D12,'Cesar'!D12,'Marian'!D12,'Guille'!D12,'Pela'!D12,'Rodri'!D12,'Pablo'!D12),0),"") | E12: =IFERROR(ROUND(AVERAGE('Marcelo'!E12,'Braian'!E12,'Cesar'!E12,'Marian'!E12,'Guille'!E12,'Pela'!E12,'Rodri'!E12,'Pablo'!E12),0),"") | F12: =IFERROR(ROUND(AVERAGE('Marcelo'!F12,'Braian'!F12,'Cesar'!F12,'Marian'!F12,'Guille'!F12,'Pela'!F12,'Rodri'!F12,'Pablo'!F12),0),"") | G12: =IFERROR(ROUND(AVERAGE('Marcelo'!G12,'Braian'!G12,'Cesar'!G12,'Marian'!G12,'Guille'!G12,'Pela'!G12,'Rodri'!G12,'Pablo'!G12),0),"") | H12: =IFERROR(ROUND(AVERAGE('Marcelo'!H12,'Braian'!H12,'Cesar'!H12,'Marian'!H12,'Guille'!H12,'Pela'!H12,'Rodri'!H12,'Pablo'!H12),0),"") | I12: =IFERROR(ROUND(AVERAGE('Marcelo'!I12,'Braian'!I12,'Cesar'!I12,'Marian'!I12,'Guille'!I12,'Pela'!I12,'Rodri'!I12,'Pablo'!I12),0),"") | J12: =IFERROR(ROUND(AVERAGE('Marcelo'!J12,'Braian'!J12,'Cesar'!J12,'Marian'!J12,'Guille'!J12,'Pela'!J12,'Rodri'!J12,'Pablo'!J12),0),"") | K12: =IFERROR(ROUND(AVERAGE('Marcelo'!K12,'Braian'!K12,'Cesar'!K12,'Marian'!K12,'Guille'!K12,'Pela'!K12,'Rodri'!K12,'Pablo'!K12),0),"") | L12: =TEXTJOIN(" | ",TRUE,'Marcelo'!L12,'Braian'!L12,'Cesar'!L12,'Marian'!L12,'Guille'!L12,'Pela'!L12,'Rodri'!L12,'Pablo'!L12)
A13: ELIAN | B13: DEF/DEL | C13: lento | D13: =IFERROR(ROUND(AVERAGE('Marcelo'!D13,'Braian'!D13,'Cesar'!D13,'Marian'!D13,'Guille'!D13,'Pela'!D13,'Rodri'!D13,'Pablo'!D13),0),"") | E13: =IFERROR(ROUND(AVERAGE('Marcelo'!E13,'Braian'!E13,'Cesar'!E13,'Marian'!E13,'Guille'!E13,'Pela'!E13,'Rodri'!E13,'Pablo'!E13),0),"") | F13: =IFERROR(ROUND(AVERAGE('Marcelo'!F13,'Braian'!F13,'Cesar'!F13,'Marian'!F13,'Guille'!F13,'Pela'!F13,'Rodri'!F13,'Pablo'!F13),0),"") | G13: =IFERROR(ROUND(AVERAGE('Marcelo'!G13,'Braian'!G13,'Cesar'!G13,'Marian'!G13,'Guille'!G13,'Pela'!G13,'Rodri'!G13,'Pablo'!G13),0),"") | H13: =IFERROR(ROUND(AVERAGE('Marcelo'!H13,'Braian'!H13,'Cesar'!H13,'Marian'!H13,'Guille'!H13,'Pela'!H13,'Rodri'!H13,'Pablo'!H13),0),"") | I13: =IFERROR(ROUND(AVERAGE('Marcelo'!I13,'Braian'!I13,'Cesar'!I13,'Marian'!I13,'Guille'!I13,'Pela'!I13,'Rodri'!I13,'Pablo'!I13),0),"") | J13: =IFERROR(ROUND(AVERAGE('Marcelo'!J13,'Braian'!J13,'Cesar'!J13,'Marian'!J13,'Guille'!J13,'Pela'!J13,'Rodri'!J13,'Pablo'!J13),0),"") | K13: =IFERROR(ROUND(AVERAGE('Marcelo'!K13,'Braian'!K13,'Cesar'!K13,'Marian'!K13,'Guille'!K13,'Pela'!K13,'Rodri'!K13,'Pablo'!K13),0),"") | L13: =TEXTJOIN(" | ",TRUE,'Marcelo'!L13,'Braian'!L13,'Cesar'!L13,'Marian'!L13,'Guille'!L13,'Pela'!L13,'Rodri'!L13,'Pablo'!L13)
... A43: VIKINGO | B43: MED/LAT | C43: rapido | D43: =IFERROR(ROUND(AVERAGE('Marcelo'!D43,'Braian'!D43,'Cesar'!D43,'Marian'!D43,'Guille'!D43,'Pela'!D43,'Rodri'!D43,'Pablo'!D43),0),"") | E43: =IFERROR(ROUND(AVERAGE('Marcelo'!E43,'Braian'!E43,'Cesar'!E43,'Marian'!E43,'Guille'!E43,'Pela'!E43,'Rodri'!E43,'Pablo'!E43),0),"") | F43: =IFERROR(ROUND(AVERAGE('Marcelo'!F43,'Braian'!F43,'Cesar'!F43,'Marian'!F43,'Guille'!F43,'Pela'!F43,'Rodri'!F43,'Pablo'!F43),0),"") | G43: =IFERROR(ROUND(AVERAGE('Marcelo'!G43,'Braian'!G43,'Cesar'!G43,'Marian'!G43,'Guille'!G43,'Pela'!G43,'Rodri'!G43,'Pablo'!G43),0),"") | H43: =IFERROR(ROUND(AVERAGE('Marcelo'!H43,'Braian'!H43,'Cesar'!H43,'Marian'!H43,'Guille'!H43,'Pela'!H43,'Rodri'!H43,'Pablo'!H43),0),"") | I43: =IFERROR(ROUND(AVERAGE('Marcelo'!I43,'Braian'!I43,'Cesar'!I43,'Marian'!I43,'Guille'!I43,'Pela'!I43,'Rodri'!I43,'Pablo'!I43),0),"") | J43: =IFERROR(ROUND(AVERAGE('Marcelo'!J43,'Braian'!J43,'Cesar'!J43,'Marian'!J43,'Guille'!J43,'Pela'!J43,'Rodri'!J43,'Pablo'!J43),0),"") | K43: =IFERROR(ROUND(AVERAGE('Marcelo'!K43,'Braian'!K43,'Cesar'!K43,'Marian'!K43,'Guille'!K43,'Pela'!K43,'Rodri'!K43,'Pablo'!K43),0),"") | L43: =TEXTJOIN(" | ",TRUE,'Marcelo'!L43,'Braian'!L43,'Cesar'!L43,'Marian'!L43,'Guille'!L43,'Pela'!L43,'Rodri'!L43,'Pablo'!L43)

Sheet Marcelo
A1: Nombre jugador | B1: Posiciones | C1: Ritmo base | D1: Ataque | E1: Solidez | F1: Tecnica | G1: Ritmo | H1: Equipo | I1: Mentalidad | J1: Regularidad | K1: Arquero | L1: Comentarios
A2: ALE CUERVO | B2: LAT/MED | C2: lento | D2: 60 | E2: 56 | F2: 71 | G2: 64 | H2: 64 | I2: 50 | J2: 60 | K2: 76
A3: ALEXIS | B3: LAT/MED | C3: rapido | D3: 76 | E3: 76 | F3: 80 | G3: 90 | H3: 71 | I3: 85 | J3: 90 | K3: 71
A4: ANIBAL | B4: DEL | C4: lento | D4: 77 | E4: 45 | F4: 76 | G4: 40 | H4: 45 | I4: 50 | J4: 60 | K4: 85
A5: AUGUSTO | B5: MED/LAT | C5: rapido | D5: 77 | E5: 71 | F5: 85 | G5: 85 | H5: 80 | I5: 60 | J5: 56 | K5: 76
A6: BETO | B6: DEL/MED | C6: lento | D6: 77 | E6: 45 | F6: 76 | G6: 50 | H6: 64 | I6: 76 | J6: 81 | K6: 71
A7: BRIAN | B7: DEL/MED | C7: rapido | D7: 95 | E7: 80 | F7: 95 | G7: 80 | H7: 85 | I7: 60 | J7: 90
A8: CAMILO | B8: MED/DEL | C8: rapido | D8: 80 | E8: 64 | F8: 92 | G8: 85 | H8: 81 | I8: 81 | J8: 81 | K8: 71
A9: CESAR | B9: DEF/LAT | C9: rapido | D9: 76 | E9: 88 | F9: 85 | G9: 71 | H9: 82 | I9: 76 | J9: 90
A10: COMANCHE | B10: LAT/MED | C10: lento | D10: 60 | E10: 58 | F10: 76 | G10: 48 | H10: 45 | I10: 64 | J10: 64 | K10: 80
A11: CRISTIAN | B11: DEL/ARQ | C11: lento | D11: 56 | E11: 40 | F11: 60 | G11: 50 | H11: 60 | I11: 80 | J11: 60 | K11: 76
A12: CUERVO | B12: DEL/DEF | C12: rapido | D12: 99 | E12: 76 | F12: 95 | G12: 76 | H12: 60 | I12: 71 | J12: 60
A13: ELIAN | B13: DEF/DEL | C13: lento | D13: 50 | E13: 40 | F13: 62 | G13: 40 | H13: 60 | I13: 60 | J13: 48 | K13: 71
A14: FACU | B14: DEF/DEL | C14: lento | D14: 56 | E14: 82 | F14: 62 | G14: 60 | H14: 64 | I14: 56 | J14: 80 | K14: 60
A15: FRANCISCO | B15: ARQ/DEL | C15: lento | D15: 40 | E15: 50 | F15: 40 | G15: 64 | H15: 50 | I15: 76 | J15: 60 | K15: 76
A16: FRANCO COMOLLI | B16: MED/DEL | C16: rapido | D16: 85 | E16: 85 | F16: 92 | G16: 90 | H16: 90 | I16: 90 | J16: 95 | K16: 71
A17: FRANCOK | B17: ARQ/LAT | C17: rapido | D17: 40 | E17: 60 | F17: 56 | G17: 76 | H17: 64 | I17: 64 | J17: 71 | K17: 80
A18: FRANQUITO | B18: MED | C18: rapido | D18: 72 | E18: 64 | F18: 80 | G18: 85 | H18: 71 | I18: 71 | J18: 81 | K18: 76
A19: GONZA | B19: ARQ/DEF | C19: lento | D19: 56 | E19: 80 | F19: 64 | G19: 64 | H19: 71 | I19: 71 | J19: 80 | K19: 80
A20: GUILLE | B20: LAT/ARQ | C20: lento | D20: 50 | E20: 40 | F20: 56 | G20: 40 | H20: 60 | I20: 80 | J20: 60 | K20: 71
A21: ISMA | B21: MED/LAT | C21: rapido | D21: 76 | E21: 80 | F21: 90 | G21: 80 | H21: 88 | I21: 85 | J21: 85 | K21: 76
A22: JAVI | B22: DEF/ARQ | C22: lento | D22: 60 | E22: 77 | F22: 69 | G22: 64 | H22: 71 | I22: 80 | J22: 64 | K22: 90
A23: JEAN FRANCO | B23: DEL | C23: lento | D23: 48 | E23: 48 | F23: 64 | G23: 64 | H23: 64 | I23: 81 | J23: 50 | K23: 56
A24: MANU | B24: LAT/MED | C24: rapido | D24: 84 | E24: 90 | F24: 85 | G24: 99 | H24: 85 | I24: 71 | J24: 90
A25: MARCELO | B25: MED/LAT | C25: lento | D25: 58 | E25: 45 | F25: 77 | G25: 50 | H25: 84 | I25: 40 | J25: 56 | K25: 71
A26: MARIAN | B26: DEL/MED | C26: lento | D26: 85 | E26: 45 | F26: 82 | G26: 50 | H26: 76 | I26: 60 | J26: 71 | K26: 80
A27: MATI BRAIAN | B27: DEF/MED | C27: rapido | D27: 76 | E27: 71 | F27: 80 | G27: 90 | H27: 56 | I27: 60 | J27: 71 | K27: 72
A28: MATI ROSALES | B28: MED/LAT | C28: rapido | D28: 80 | E28: 82 | F28: 99 | G28: 76 | H28: 95 | I28: 80 | J28: 85
A29: MAURI | B29: DEL | C29: rapido | D29: 80 | E29: 56 | F29: 71 | G29: 81 | H29: 71 | I29: 80 | J29: 76 | K29: 71
A30: MAXI | B30: MED | C30: lento | D30: 60 | E30: 45 | F30: 76 | G30: 48 | H30: 64 | I30: 60 | J30: 50 | K30: 54
A31: NICO | B31: MED/LAT | C31: rapido | D31: 80 | E31: 56 | F31: 80 | G31: 71 | H31: 80 | I31: 71 | J31: 71 | K31: 71
A32: PABLO | B32: DEF/LAT | C32: rapido | D32: 64 | E32: 92 | F32: 80 | G32: 80 | H32: 80 | I32: 95 | J32: 95
A33: PABLO CASTILLO | B33: LAT/MED | C33: lento | D33: 64 | E33: 80 | F33: 80 | G33: 64 | H33: 85 | I33: 76 | J33: 64 | K33: 71
A34: PABLO GARCIA | B34: MED/LAT | C34: rapido | D34: 51 | E34: 64 | F34: 58 | G34: 71 | H34: 71 | I34: 85 | J34: 80 | K34: 71
A35: PELA | B35: DEL/MED | C35: rapido | D35: 85 | E35: 76 | F35: 85 | G35: 76 | H35: 60 | I35: 85 | J35: 50 | K35: 76
A36: PULY | B36: DEL/MED | C36: lento | D36: 64 | E36: 35 | F36: 92 | G36: 50 | H36: 64 | I36: 50 | J36: 50 | K36: 71
A37: RODRI CHAVEZ | B37: LAT/MED | C37: rapido | D37: 76 | E37: 82 | F37: 80 | G37: 85 | H37: 85 | I37: 90 | J37: 90 | K37: 76
A38: RODRI SUAREZ | B38: DEF/ARQ | C38: lento | D38: 50 | E38: 77 | F38: 60 | G38: 64 | H38: 76 | I38: 80 | J38: 80 | K38: 80
A39: SANTI | B39: ARQ/MED | C39: rapido | D39: 64 | E39: 64 | F39: 92 | G39: 81 | H39: 64 | I39: 64 | J39: 81 | K39: 71
A40: SEBACORTEZ | B40: DEF/ARQ | C40: lento | D40: 71 | E40: 82 | F40: 80 | G40: 60 | H40: 76 | I40: 85 | J40: 64 | K40: 90
...

Sheet Braian
A1: Nombre jugador | B1: Posiciones | C1: Ritmo base | D1: Ataque | E1: Solidez | F1: Tecnica | G1: Ritmo | H1: Equipo | I1: Mentalidad | J1: Regularidad | K1: Arquero | L1: Comentarios
A2: ALE CUERVO | B2: LAT/MED | C2: lento | D2: 60 | E2: 56 | F2: 71 | G2: 64 | H2: 64 | I2: 50 | J2: 60 | K2: 76
A3: ALEXIS | B3: LAT/MED | C3: rapido | D3: 76 | E3: 76 | F3: 80 | G3: 90 | H3: 71 | I3: 85 | J3: 90 | K3: 71
A4: ANIBAL | B4: DEL | C4: lento | D4: 77 | E4: 45 | F4: 76 | G4: 40 | H4: 45 | I4: 50 | J4: 60 | K4: 85
A5: AUGUSTO | B5: MED/LAT | C5: rapido | D5: 77 | E5: 71 | F5: 85 | G5: 85 | H5: 80 | I5: 60 | J5: 56 | K5: 76
A6: BETO | B6: DEL/MED | C6: lento | D6: 77 | E6: 45 | F6: 76 | G6: 50 | H6: 64 | I6: 76 | J6: 81 | K6: 71
A7: BRIAN | B7: DEL/MED | C7: rapido | D7: 95 | E7: 80 | F7: 95 | G7: 80 | H7: 85 | I7: 60 | J7: 90
A8: CAMILO | B8: MED/DEL | C8: rapido | D8: 80 | E8: 64 | F8: 92 | G8: 85 | H8: 81 | I8: 81 | J8: 81 | K8: 71
A9: CESAR | B9: DEF/LAT | C9: rapido | D9: 76 | E9: 88 | F9: 85 | G9: 71 | H9: 82 | I9: 76 | J9: 90
A10: COMANCHE | B10: LAT/MED | C10: lento | D10: 60 | E10: 58 | F10: 76 | G10: 48 | H10: 45 | I10: 64 | J10: 64 | K10: 80
A11: CRISTIAN | B11: DEL/ARQ | C11: lento | D11: 56 | E11: 40 | F11: 60 | G11: 50 | H11: 60 | I11: 80 | J11: 60 | K11: 76
A12: CUERVO | B12: DEL/DEF | C12: rapido | D12: 99 | E12: 76 | F12: 95 | G12: 76 | H12: 60 | I12: 71 | J12: 60
A13: ELIAN | B13: DEF/DEL | C13: lento | D13: 50 | E13: 40 | F13: 62 | G13: 40 | H13: 60 | I13: 60 | J13: 48 | K13: 71
A14: FACU | B14: DEF/DEL | C14: lento | D14: 56 | E14: 82 | F14: 62 | G14: 60 | H14: 64 | I14: 56 | J14: 80 | K14: 60
A15: FRANCISCO | B15: ARQ/DEL | C15: lento | D15: 40 | E15: 50 | F15: 40 | G15: 64 | H15: 50 | I15: 76 | J15: 60 | K15: 76
A16: FRANCO COMOLLI | B16: MED/DEL | C16: rapido | D16: 85 | E16: 85 | F16: 92 | G16: 90 | H16: 90 | I16: 90 | J16: 95 | K16: 71
A17: FRANCOK | B17: ARQ/LAT | C17: rapido | D17: 40 | E17: 60 | F17: 56 | G17: 76 | H17: 64 | I17: 64 | J17: 71 | K17: 80
A18: FRANQUITO | B18: MED | C18: rapido | D18: 72 | E18: 64 | F18: 80 | G18: 85 | H18: 71 | I18: 71 | J18: 81 | K18: 76
A19: GONZA | B19: ARQ/DEF | C19: lento | D19: 56 | E19: 80 | F19: 64 | G19: 64 | H19: 71 | I19: 71 | J19: 80 | K19: 80
A20: GUILLE | B20: LAT/ARQ | C20: lento | D20: 50 | E20: 40 | F20: 56 | G20: 40 | H20: 60 | I20: 80 | J20: 60 | K20: 71
A21: ISMA | B21: MED/LAT | C21: rapido | D21: 76 | E21: 80 | F21: 90 | G21: 80 | H21: 88 | I21: 85 | J21: 85 | K21: 76
A22: JAVI | B22: DEF/ARQ | C22: lento | D22: 60 | E22: 77 | F22: 69 | G22: 64 | H22: 71 | I22: 80 | J22: 64 | K22: 90
A23: JEAN FRANCO | B23: DEL | C23: lento | D23: 48 | E23: 48 | F23: 64 | G23: 64 | H23: 64 | I23: 81 | J23: 50 | K23: 56
A24: MANU | B24: LAT/MED | C24: rapido | D24: 84 | E24: 90 | F24: 85 | G24: 99 | H24: 85 | I24: 71 | J24: 90
A25: MARCELO | B25: MED/LAT | C25: lento | D25: 58 | E25: 45 | F25: 77 | G25: 50 | H25: 84 | I25: 40 | J25: 56 | K25: 71
A26: MARIAN | B26: DEL/MED | C26: lento | D26: 85 | E26: 45 | F26: 82 | G26: 50 | H26: 76 | I26: 60 | J26: 71 | K26: 80
A27: MATI BRAIAN | B27: DEF/MED | C27: rapido | D27: 76 | E27: 71 | F27: 80 | G27: 90 | H27: 56 | I27: 60 | J27: 71 | K27: 72
A28: MATI ROSALES | B28: MED/LAT | C28: rapido | D28: 80 | E28: 82 | F28: 99 | G28: 76 | H28: 95 | I28: 80 | J28: 85
A29: MAURI | B29: DEL | C29: rapido | D29: 80 | E29: 56 | F29: 71 | G29: 81 | H29: 71 | I29: 80 | J29: 76 | K29: 71
A30: MAXI | B30: MED | C30: lento | D30: 60 | E30: 45 | F30: 76 | G30: 48 | H30: 64 | I30: 60 | J30: 50 | K30: 54
A31: NICO | B31: MED/LAT | C31: rapido | D31: 80 | E31: 56 | F31: 80 | G31: 71 | H31: 80 | I31: 71 | J31: 71 | K31: 71
A32: PABLO | B32: DEF/LAT | C32: rapido | D32: 64 | E32: 92 | F32: 80 | G32: 80 | H32: 80 | I32: 95 | J32: 95
A33: PABLO CASTILLO | B33: LAT/MED | C33: lento | D33: 64 | E33: 80 | F33: 80 | G33: 64 | H33: 85 | I33: 76 | J33: 64 | K33: 71
A34: PABLO GARCIA | B34: MED/LAT | C34: rapido | D34: 51 | E34: 64 | F34: 58 | G34: 71 | H34: 71 | I34: 85 | J34: 80 | K34: 71
A35: PELA | B35: DEL/MED | C35: rapido | D35: 85 | E35: 76 | F35: 85 | G35: 76 | H35: 60 | I35: 85 | J35: 50 | K35: 76
A36: PULY | B36: DEL/MED | C36: lento | D36: 64 | E36: 35 | F36: 92 | G36: 50 | H36: 64 | I36: 50 | J36: 50 | K36: 71
A37: RODRI CHAVEZ | B37: LAT/MED | C37: rapido | D37: 76 | E37: 82 | F37: 80 | G37: 85 | H37: 85 | I37: 90 | J37: 90 | K37: 76
A38: RODRI SUAREZ | B38: DEF/ARQ | C38: lento | D38: 50 | E38: 77 | F38: 60 | G38: 64 | H38: 76 | I38: 80 | J38: 80 | K38: 80
A39: SANTI | B39: ARQ/MED | C39: rapido | D39: 64 | E39: 64 | F39: 92 | G39: 81 | H39: 64 | I39: 64 | J39: 81 | K39: 71
A40: SEBACORTEZ | B40: DEF/ARQ | C40: lento | D40: 71 | E40: 82 | F40: 80 | G40: 60 | H40: 76 | I40: 85 | J40: 64 | K40: 90
...

Sheet Cesar
A1: Nombre jugador | B1: Posiciones | C1: Ritmo base | D1: Ataque | E1: Solidez | F1: Tecnica | G1: Ritmo | H1: Equipo | I1: Mentalidad | J1: Regularidad | K1: Arquero | L1: Comentarios
A2: ALE CUERVO | B2: LAT/MED | C2: lento | D2: 60 | E2: 56 | F2: 71 | G2: 64 | H2: 64 | I2: 50 | J2: 60 | K2: 76
A3: ALEXIS | B3: LAT/MED | C3: rapido | D3: 76 | E3: 76 | F3: 80 | G3: 90 | H3: 71 | I3: 85 | J3: 90 | K3: 71
A4: ANIBAL | B4: DEL | C4: lento | D4: 77 | E4: 45 | F4: 76 | G4: 40 | H4: 45 | I4: 50 | J4: 60 | K4: 85
A5: AUGUSTO | B5: MED/LAT | C5: rapido | D5: 77 | E5: 71 | F5: 85 | G5: 85 | H5: 80 | I5: 60 | J5: 56 | K5: 76
A6: BETO | B6: DEL/MED | C6: lento | D6: 77 | E6: 45 | F6: 76 | G6: 50 | H6: 64 | I6: 76 | J6: 81 | K6: 71
A7: BRIAN | B7: DEL/MED | C7: rapido | D7: 95 | E7: 80 | F7: 95 | G7: 80 | H7: 85 | I7: 60 | J7: 90
A8: CAMILO | B8: MED/DEL | C8: rapido | D8: 80 | E8: 64 | F8: 92 | G8: 85 | H8: 81 | I8: 81 | J8: 81 | K8: 71
A9: CESAR | B9: DEF/LAT | C9: rapido | D9: 76 | E9: 88 | F9: 85 | G9: 71 | H9: 82 | I9: 76 | J9: 90
A10: COMANCHE | B10: LAT/MED | C10: lento | D10: 60 | E10: 58 | F10: 76 | G10: 48 | H10: 45 | I10: 64 | J10: 64 | K10: 80
A11: CRISTIAN | B11: DEL/ARQ | C11: lento | D11: 56 | E11: 40 | F11: 60 | G11: 50 | H11: 60 | I11: 80 | J11: 60 | K11: 76
A12: CUERVO | B12: DEL/DEF | C12: rapido | D12: 99 | E12: 76 | F12: 95 | G12: 76 | H12: 60 | I12: 71 | J12: 60
A13: ELIAN | B13: DEF/DEL | C13: lento | D13: 50 | E13: 40 | F13: 62 | G13: 40 | H13: 60 | I13: 60 | J13: 48 | K13: 71
A14: FACU | B14: DEF/DEL | C14: lento | D14: 56 | E14: 82 | F14: 62 | G14: 60 | H14: 64 | I14: 56 | J14: 80 | K14: 60
A15: FRANCISCO | B15: ARQ/DEL | C15: lento | D15: 40 | E15: 50 | F15: 40 | G15: 64 | H15: 50 | I15: 76 | J15: 60 | K15: 76
A16: FRANCO COMOLLI | B16: MED/DEL | C16: rapido | D16: 85 | E16: 85 | F16: 92 | G16: 90 | H16: 90 | I16: 90 | J16: 95 | K16: 71
A17: FRANCOK | B17: ARQ/LAT | C17: rapido | D17: 40 | E17: 60 | F17: 56 | G17: 76 | H17: 64 | I17: 64 | J17: 71 | K17: 80
A18: FRANQUITO | B18: MED | C18: rapido | D18: 72 | E18: 64 | F18: 80 | G18: 85 | H18: 71 | I18: 71 | J18: 81 | K18: 76
A19: GONZA | B19: ARQ/DEF | C19: lento | D19: 56 | E19: 80 | F19: 64 | G19: 64 | H19: 71 | I19: 71 | J19: 80 | K19: 80
A20: GUILLE | B20: LAT/ARQ | C20: lento | D20: 50 | E20: 40 | F20: 56 | G20: 40 | H20: 60 | I20: 80 | J20: 60 | K20: 71
A21: ISMA | B21: MED/LAT | C21: rapido | D21: 76 | E21: 80 | F21: 90 | G21: 80 | H21: 88 | I21: 85 | J21: 85 | K21: 76
A22: JAVI | B22: DEF/ARQ | C22: lento | D22: 60 | E22: 77 | F22: 69 | G22: 64 | H22: 71 | I22: 80 | J22: 64 | K22: 90
A23: JEAN FRANCO | B23: DEL | C23: lento | D23: 48 | E23: 48 | F23: 64 | G23: 64 | H23: 64 | I23: 81 | J23: 50 | K23: 56
A24: MANU | B24: LAT/MED | C24: rapido | D24: 84 | E24: 90 | F24: 85 | G24: 99 | H24: 85 | I24: 71 | J24: 90
A25: MARCELO | B25: MED/LAT | C25: lento | D25: 58 | E25: 45 | F25: 77 | G25: 50 | H25: 84 | I25: 40 | J25: 56 | K25: 71
A26: MARIAN | B26: DEL/MED | C26: lento | D26: 85 | E26: 45 | F26: 82 | G26: 50 | H26: 76 | I26: 60 | J26: 71 | K26: 80
A27: MATI BRAIAN | B27: DEF/MED | C27: rapido | D27: 76 | E27: 71 | F27: 80 | G27: 90 | H27: 56 | I27: 60 | J27: 71 | K27: 72
A28: MATI ROSALES | B28: MED/LAT | C28: rapido | D28: 80 | E28: 82 | F28: 99 | G28: 76 | H28: 95 | I28: 80 | J28: 85
A29: MAURI | B29: DEL | C29: rapido | D29: 80 | E29: 56 | F29: 71 | G29: 81 | H29: 71 | I29: 80 | J29: 76 | K29: 71
A30: MAXI | B30: MED | C30: lento | D30: 60 | E30: 45 | F30: 76 | G30: 48 | H30: 64 | I30: 60 | J30: 50 | K30: 54
A31: NICO | B31: MED/LAT | C31: rapido | D31: 80 | E31: 56 | F31: 80 | G31: 71 | H31: 80 | I31: 71 | J31: 71 | K31: 71
A32: PABLO | B32: DEF/LAT | C32: rapido | D32: 64 | E32: 92 | F32: 80 | G32: 80 | H32: 80 | I32: 95 | J32: 95
A33: PABLO CASTILLO | B33: LAT/MED | C33: lento | D33: 64 | E33: 80 | F33: 80 | G33: 64 | H33: 85 | I33: 76 | J33: 64 | K33: 71
A34: PABLO GARCIA | B34: MED/LAT | C34: rapido | D34: 51 | E34: 64 | F34: 58 | G34: 71 | H34: 71 | I34: 85 | J34: 80 | K34: 71
A35: PELA | B35: DEL/MED | C35: rapido | D35: 85 | E35: 76 | F35: 85 | G35: 76 | H35: 60 | I35: 85 | J35: 50 | K35: 76
A36: PULY | B36: DEL/MED | C36: lento | D36: 64 | E36: 35 | F36: 92 | G36: 50 | H36: 64 | I36: 50 | J36: 50 | K36: 71
A37: RODRI CHAVEZ | B37: LAT/MED | C37: rapido | D37: 76 | E37: 82 | F37: 80 | G37: 85 | H37: 85 | I37: 90 | J37: 90 | K37: 76
A38: RODRI SUAREZ | B38: DEF/ARQ | C38: lento | D38: 50 | E38: 77 | F38: 60 | G38: 64 | H38: 76 | I38: 80 | J38: 80 | K38: 80
A39: SANTI | B39: ARQ/MED | C39: rapido | D39: 64 | E39: 64 | F39: 92 | G39: 81 | H39: 64 | I39: 64 | J39: 81 | K39: 71
A40: SEBACORTEZ | B40: DEF/ARQ | C40: lento | D40: 71 | E40: 82 | F40: 80 | G40: 60 | H40: 76 | I40: 85 | J40: 64 | K40: 90
...

Sheet Marian
A1: Nombre jugador | B1: Posiciones | C1: Ritmo base | D1: Ataque | E1: Solidez | F1: Tecnica | G1: Ritmo | H1: Equipo | I1: Mentalidad | J1: Regularidad | K1: Arquero | L1: Comentarios
A2: ALE CUERVO | B2: LAT/MED | C2: lento | D2: 60 | E2: 56 | F2: 71 | G2: 64 | H2: 64 | I2: 50 | J2: 60 | K2: 76
A3: ALEXIS | B3: LAT/MED | C3: rapido | D3: 76 | E3: 76 | F3: 80 | G3: 90 | H3: 71 | I3: 85 | J3: 90 | K3: 71
A4: ANIBAL | B4: DEL | C4: lento | D4: 77 | E4: 45 | F4: 76 | G4: 40 | H4: 45 | I4: 50 | J4: 60 | K4: 85
A5: AUGUSTO | B5: MED/LAT | C5: rapido | D5: 77 | E5: 71 | F5: 85 | G5: 85 | H5: 80 | I5: 60 | J5: 56 | K5: 76
A6: BETO | B6: DEL/MED | C6: lento | D6: 77 | E6: 45 | F6: 76 | G6: 50 | H6: 64 | I6: 76 | J6: 81 | K6: 71
A7: BRIAN | B7: DEL/MED | C7: rapido | D7: 95 | E7: 80 | F7: 95 | G7: 80 | H7: 85 | I7: 60 | J7: 90
A8: CAMILO | B8: MED/DEL | C8: rapido | D8: 80 | E8: 64 | F8: 92 | G8: 85 | H8: 81 | I8: 81 | J8: 81 | K8: 71
A9: CESAR | B9: DEF/LAT | C9: rapido | D9: 76 | E9: 88 | F9: 85 | G9: 71 | H9: 82 | I9: 76 | J9: 90
A10: COMANCHE | B10: LAT/MED | C10: lento | D10: 60 | E10: 58 | F10: 76 | G10: 48 | H10: 45 | I10: 64 | J10: 64 | K10: 80
A11: CRISTIAN | B11: DEL/ARQ | C11: lento | D11: 56 | E11: 40 | F11: 60 | G11: 50 | H11: 60 | I11: 80 | J11: 60 | K11: 76
A12: CUERVO | B12: DEL/DEF | C12: rapido | D12: 99 | E12: 76 | F12: 95 | G12: 76 | H12: 60 | I12: 71 | J12: 60
A13: ELIAN | B13: DEF/DEL | C13: lento | D13: 50 | E13: 40 | F13: 62 | G13: 40 | H13: 60 | I13: 60 | J13: 48 | K13: 71
A14: FACU | B14: DEF/DEL | C14: lento | D14: 56 | E14: 82 | F14: 62 | G14: 60 | H14: 64 | I14: 56 | J14: 80 | K14: 60
A15: FRANCISCO | B15: ARQ/DEL | C15: lento | D15: 40 | E15: 50 | F15: 40 | G15: 64 | H15: 50 | I15: 76 | J15: 60 | K15: 76
A16: FRANCO COMOLLI | B16: MED/DEL | C16: rapido | D16: 85 | E16: 85 | F16: 92 | G16: 90 | H16: 90 | I16: 90 | J16: 95 | K16: 71
A17: FRANCOK | B17: ARQ/LAT | C17: rapido | D17: 40 | E17: 60 | F17: 56 | G17: 76 | H17: 64 | I17: 64 | J17: 71 | K17: 80
A18: FRANQUITO | B18: MED | C18: rapido | D18: 72 | E18: 64 | F18: 80 | G18: 85 | H18: 71 | I18: 71 | J18: 81 | K18: 76
A19: GONZA | B19: ARQ/DEF | C19: lento | D19: 56 | E19: 80 | F19: 64 | G19: 64 | H19: 71 | I19: 71 | J19: 80 | K19: 80
A20: GUILLE | B20: LAT/ARQ | C20: lento | D20: 50 | E20: 40 | F20: 56 | G20: 40 | H20: 60 | I20: 80 | J20: 60 | K20: 71
A21: ISMA | B21: MED/LAT | C21: rapido | D21: 76 | E21: 80 | F21: 90 | G21: 80 | H21: 88 | I21: 85 | J21: 85 | K21: 76
A22: JAVI | B22: DEF/ARQ | C22: lento | D22: 60 | E22: 77 | F22: 69 | G22: 64 | H22: 71 | I22: 80 | J22: 64 | K22: 90
A23: JEAN FRANCO | B23: DEL | C23: lento | D23: 48 | E23: 48 | F23: 64 | G23: 64 | H23: 64 | I23: 81 | J23: 50 | K23: 56
A24: MANU | B24: LAT/MED | C24: rapido | D24: 84 | E24: 90 | F24: 85 | G24: 99 | H24: 85 | I24: 71 | J24: 90
A25: MARCELO | B25: MED/LAT | C25: lento | D25: 58 | E25: 45 | F25: 77 | G25: 50 | H25: 84 | I25: 40 | J25: 56 | K25: 71
A26: MARIAN | B26: DEL/MED | C26: lento | D26: 85 | E26: 45 | F26: 82 | G26: 50 | H26: 76 | I26: 60 | J26: 71 | K26: 80
A27: MATI BRAIAN | B27: DEF/MED | C27: rapido | D27: 76 | E27: 71 | F27: 80 | G27: 90 | H27: 56 | I27: 60 | J27: 71 | K27: 72
A28: MATI ROSALES | B28: MED/LAT | C28: rapido | D28: 80 | E28: 82 | F28: 99 | G28: 76 | H28: 95 | I28: 80 | J28: 85
A29: MAURI | B29: DEL | C29: rapido | D29: 80 | E29: 56 | F29: 71 | G29: 81 | H29: 71 | I29: 80 | J29: 76 | K29: 71
A30: MAXI | B30: MED | C30: lento | D30: 60 | E30: 45 | F30: 76 | G30: 48 | H30: 64 | I30: 60 | J30: 50 | K30: 54
A31: NICO | B31: MED/LAT | C31: rapido | D31: 80 | E31: 56 | F31: 80 | G31: 71 | H31: 80 | I31: 71 | J31: 71 | K31: 71
A32: PABLO | B32: DEF/LAT | C32: rapido | D32: 64 | E32: 92 | F32: 80 | G32: 80 | H32: 80 | I32: 95 | J32: 95
A33: PABLO CASTILLO | B33: LAT/MED | C33: lento | D33: 64 | E33: 80 | F33: 80 | G33: 64 | H33: 85 | I33: 76 | J33: 64 | K33: 71
A34: PABLO GARCIA | B34: MED/LAT | C34: rapido | D34: 51 | E34: 64 | F34: 58 | G34: 71 | H34: 71 | I34: 85 | J34: 80 | K34: 71
A35: PELA | B35: DEL/MED | C35: rapido | D35: 85 | E35: 76 | F35: 85 | G35: 76 | H35: 60 | I35: 85 | J35: 50 | K35: 76
A36: PULY | B36: DEL/MED | C36: lento | D36: 64 | E36: 35 | F36: 92 | G36: 50 | H36: 64 | I36: 50 | J36: 50 | K36: 71
A37: RODRI CHAVEZ | B37: LAT/MED | C37: rapido | D37: 76 | E37: 82 | F37: 80 | G37: 85 | H37: 85 | I37: 90 | J37: 90 | K37: 76
A38: RODRI SUAREZ | B38: DEF/ARQ | C38: lento | D38: 50 | E38: 77 | F38: 60 | G38: 64 | H38: 76 | I38: 80 | J38: 80 | K38: 80
A39: SANTI | B39: ARQ/MED | C39: rapido | D39: 64 | E39: 64 | F39: 92 | G39: 81 | H39: 64 | I39: 64 | J39: 81 | K39: 71
A40: SEBACORTEZ | B40: DEF/ARQ | C40: lento | D40: 71 | E40: 82 | F40: 80 | G40: 60 | H40: 76 | I40: 85 | J40: 64 | K40: 90
...

Sheet Guille
A1: Nombre jugador | B1: Posiciones | C1: Ritmo base | D1: Ataque | E1: Solidez | F1: Tecnica | G1: Ritmo | H1: Equipo | I1: Mentalidad | J1: Regularidad | K1: Arquero | L1: Comentarios
A2: ALE CUERVO | B2: LAT/MED | C2: lento | D2: 60 | E2: 56 | F2: 71 | G2: 64 | H2: 64 | I2: 50 | J2: 60 | K2: 76
A3: ALEXIS | B3: LAT/MED | C3: rapido | D3: 76 | E3: 76 | F3: 80 | G3: 90 | H3: 71 | I3: 85 | J3: 90 | K3: 71
A4: ANIBAL | B4: DEL | C4: lento | D4: 77 | E4: 45 | F4: 76 | G4: 40 | H4: 45 | I4: 50 | J4: 60 | K4: 85
A5: AUGUSTO | B5: MED/LAT | C5: rapido | D5: 77 | E5: 71 | F5: 85 | G5: 85 | H5: 80 | I5: 60 | J5: 56 | K5: 76
A6: BETO | B6: DEL/MED | C6: lento | D6: 77 | E6: 45 | F6: 76 | G6: 50 | H6: 64 | I6: 76 | J6: 81 | K6: 71
A7: BRIAN | B7: DEL/MED | C7: rapido | D7: 95 | E7: 80 | F7: 95 | G7: 80 | H7: 85 | I7: 60 | J7: 90
A8: CAMILO | B8: MED/DEL | C8: rapido | D8: 80 | E8: 64 | F8: 92 | G8: 85 | H8: 81 | I8: 81 | J8: 81 | K8: 71
A9: CESAR | B9: DEF/LAT | C9: rapido | D9: 76 | E9: 88 | F9: 85 | G9: 71 | H9: 82 | I9: 76 | J9: 90
A10: COMANCHE | B10: LAT/MED | C10: lento | D10: 60 | E10: 58 | F10: 76 | G10: 48 | H10: 45 | I10: 64 | J10: 64 | K10: 80
A11: CRISTIAN | B11: DEL/ARQ | C11: lento | D11: 56 | E11: 40 | F11: 60 | G11: 50 | H11: 60 | I11: 80 | J11: 60 | K11: 76
A12: CUERVO | B12: DEL/DEF | C12: rapido | D12: 99 | E12: 76 | F12: 95 | G12: 76 | H12: 60 | I12: 71 | J12: 60
A13: ELIAN | B13: DEF/DEL | C13: lento | D13: 50 | E13: 40 | F13: 62 | G13: 40 | H13: 60 | I13: 60 | J13: 48 | K13: 71
A14: FACU | B14: DEF/DEL | C14: lento | D14: 56 | E14: 82 | F14: 62 | G14: 60 | H14: 64 | I14: 56 | J14: 80 | K14: 60
A15: FRANCISCO | B15: ARQ/DEL | C15: lento | D15: 40 | E15: 50 | F15: 40 | G15: 64 | H15: 50 | I15: 76 | J15: 60 | K15: 76
A16: FRANCO COMOLLI | B16: MED/DEL | C16: rapido | D16: 85 | E16: 85 | F16: 92 | G16: 90 | H16: 90 | I16: 90 | J16: 95 | K16: 71
A17: FRANCOK | B17: ARQ/LAT | C17: rapido | D17: 40 | E17: 60 | F17: 56 | G17: 76 | H17: 64 | I17: 64 | J17: 71 | K17: 80
A18: FRANQUITO | B18: MED | C18: rapido | D18: 72 | E18: 64 | F18: 80 | G18: 85 | H18: 71 | I18: 71 | J18: 81 | K18: 76
A19: GONZA | B19: ARQ/DEF | C19: lento | D19: 56 | E19: 80 | F19: 64 | G19: 64 | H19: 71 | I19: 71 | J19: 80 | K19: 80
A20: GUILLE | B20: LAT/ARQ | C20: lento | D20: 50 | E20: 40 | F20: 56 | G20: 40 | H20: 60 | I20: 80 | J20: 60 | K20: 71
A21: ISMA | B21: MED/LAT | C21: rapido | D21: 76 | E21: 80 | F21: 90 | G21: 80 | H21: 88 | I21: 85 | J21: 85 | K21: 76
A22: JAVI | B22: DEF/ARQ | C22: lento | D22: 60 | E22: 77 | F22: 69 | G22: 64 | H22: 71 | I22: 80 | J22: 64 | K22: 90
A23: JEAN FRANCO | B23: DEL | C23: lento | D23: 48 | E23: 48 | F23: 64 | G23: 64 | H23: 64 | I23: 81 | J23: 50 | K23: 56
A24: MANU | B24: LAT/MED | C24: rapido | D24: 84 | E24: 90 | F24: 85 | G24: 99 | H24: 85 | I24: 71 | J24: 90
A25: MARCELO | B25: MED/LAT | C25: lento | D25: 58 | E25: 45 | F25: 77 | G25: 50 | H25: 84 | I25: 40 | J25: 56 | K25: 71
A26: MARIAN | B26: DEL/MED | C26: lento | D26: 85 | E26: 45 | F26: 82 | G26: 50 | H26: 76 | I26: 60 | J26: 71 | K26: 80
A27: MATI BRAIAN | B27: DEF/MED | C27: rapido | D27: 76 | E27: 71 | F27: 80 | G27: 90 | H27: 56 | I27: 60 | J27: 71 | K27: 72
A28: MATI ROSALES | B28: MED/LAT | C28: rapido | D28: 80 | E28: 82 | F28: 99 | G28: 76 | H28: 95 | I28: 80 | J28: 85
A29: MAURI | B29: DEL | C29: rapido | D29: 80 | E29: 56 | F29: 71 | G29: 81 | H29: 71 | I29: 80 | J29: 76 | K29: 71
A30: MAXI | B30: MED | C30: lento | D30: 60 | E30: 45 | F30: 76 | G30: 48 | H30: 64 | I30: 60 | J30: 50 | K30: 54
A31: NICO | B31: MED/LAT | C31: rapido | D31: 80 | E31: 56 | F31: 80 | G31: 71 | H31: 80 | I31: 71 | J31: 71 | K31: 71
A32: PABLO | B32: DEF/LAT | C32: rapido | D32: 64 | E32: 92 | F32: 80 | G32: 80 | H32: 80 | I32: 95 | J32: 95
A33: PABLO CASTILLO | B33: LAT/MED | C33: lento | D33: 64 | E33: 80 | F33: 80 | G33: 64 | H33: 85 | I33: 76 | J33: 64 | K33: 71
A34: PABLO GARCIA | B34: MED/LAT | C34: rapido | D34: 51 | E34: 64 | F34: 58 | G34: 71 | H34: 71 | I34: 85 | J34: 80 | K34: 71
A35: PELA | B35: DEL/MED | C35: rapido | D35: 85 | E35: 76 | F35: 85 | G35: 76 | H35: 60 | I35: 85 | J35: 50 | K35: 76
A36: PULY | B36: DEL/MED | C36: lento | D36: 64 | E36: 35 | F36: 92 | G36: 50 | H36: 64 | I36: 50 | J36: 50 | K36: 71
A37: RODRI CHAVEZ | B37: LAT/MED | C37: rapido | D37: 76 | E37: 82 | F37: 80 | G37: 85 | H37: 85 | I37: 90 | J37: 90 | K37: 76
A38: RODRI SUAREZ | B38: DEF/ARQ | C38: lento | D38: 50 | E38: 77 | F38: 60 | G38: 64 | H38: 76 | I38: 80 | J38: 80 | K38: 80
A39: SANTI | B39: ARQ/MED | C39: rapido | D39: 64 | E39: 64 | F39: 92 | G39: 81 | H39: 64 | I39: 64 | J39: 81 | K39: 71
A40: SEBACORTEZ | B40: DEF/ARQ | C40: lento | D40: 71 | E40: 82 | F40: 80 | G40: 60 | H40: 76 | I40: 85 | J40: 64 | K40: 90
...

Sheet Pela
A1: Nombre jugador | B1: Posiciones | C1: Ritmo base | D1: Ataque | E1: Solidez | F1: Tecnica | G1: Ritmo | H1: Equipo | I1: Mentalidad | J1: Regularidad | K1: Arquero | L1: Comentarios
A2: ALE CUERVO | B2: LAT/MED | C2: lento | D2: 60 | E2: 56 | F2: 71 | G2: 64 | H2: 64 | I2: 50 | J2: 60 | K2: 76
A3: ALEXIS | B3: LAT/MED | C3: rapido | D3: 76 | E3: 76 | F3: 80 | G3: 90 | H3: 71 | I3: 85 | J3: 90 | K3: 71
A4: ANIBAL | B4: DEL | C4: lento | D4: 77 | E4: 45 | F4: 76 | G4: 40 | H4: 45 | I4: 50 | J4: 60 | K4: 85
A5: AUGUSTO | B5: MED/LAT | C5: rapido | D5: 77 | E5: 71 | F5: 85 | G5: 85 | H5: 80 | I5: 60 | J5: 56 | K5: 76
A6: BETO | B6: DEL/MED | C6: lento | D6: 77 | E6: 45 | F6: 76 | G6: 50 | H6: 64 | I6: 76 | J6: 81 | K6: 71
A7: BRIAN | B7: DEL/MED | C7: rapido | D7: 95 | E7: 80 | F7: 95 | G7: 80 | H7: 85 | I7: 60 | J7: 90
A8: CAMILO | B8: MED/DEL | C8: rapido | D8: 80 | E8: 64 | F8: 92 | G8: 85 | H8: 81 | I8: 81 | J8: 81 | K8: 71
A9: CESAR | B9: DEF/LAT | C9: rapido | D9: 76 | E9: 88 | F9: 85 | G9: 71 | H9: 82 | I9: 76 | J9: 90
A10: COMANCHE | B10: LAT/MED | C10: lento | D10: 60 | E10: 58 | F10: 76 | G10: 48 | H10: 45 | I10: 64 | J10: 64 | K10: 80
A11: CRISTIAN | B11: DEL/ARQ | C11: lento | D11: 56 | E11: 40 | F11: 60 | G11: 50 | H11: 60 | I11: 80 | J11: 60 | K11: 76
A12: CUERVO | B12: DEL/DEF | C12: rapido | D12: 99 | E12: 76 | F12: 95 | G12: 76 | H12: 60 | I12: 71 | J12: 60
A13: ELIAN | B13: DEF/DEL | C13: lento | D13: 50 | E13: 40 | F13: 62 | G13: 40 | H13: 60 | I13: 60 | J13: 48 | K13: 71
A14: FACU | B14: DEF/DEL | C14: lento | D14: 56 | E14: 82 | F14: 62 | G14: 60 | H14: 64 | I14: 56 | J14: 80 | K14: 60
A15: FRANCISCO | B15: ARQ/DEL | C15: lento | D15: 40 | E15: 50 | F15: 40 | G15: 64 | H15: 50 | I15: 76 | J15: 60 | K15: 76
A16: FRANCO COMOLLI | B16: MED/DEL | C16: rapido | D16: 85 | E16: 85 | F16: 92 | G16: 90 | H16: 90 | I16: 90 | J16: 95 | K16: 71
A17: FRANCOK | B17: ARQ/LAT | C17: rapido | D17: 40 | E17: 60 | F17: 56 | G17: 76 | H17: 64 | I17: 64 | J17: 71 | K17: 80
A18: FRANQUITO | B18: MED | C18: rapido | D18: 72 | E18: 64 | F18: 80 | G18: 85 | H18: 71 | I18: 71 | J18: 81 | K18: 76
A19: GONZA | B19: ARQ/DEF | C19: lento | D19: 56 | E19: 80 | F19: 64 | G19: 64 | H19: 71 | I19: 71 | J19: 80 | K19: 80
A20: GUILLE | B20: LAT/ARQ | C20: lento | D20: 50 | E20: 40 | F20: 56 | G20: 40 | H20: 60 | I20: 80 | J20: 60 | K20: 71
A21: ISMA | B21: MED/LAT | C21: rapido | D21: 76 | E21: 80 | F21: 90 | G21: 80 | H21: 88 | I21: 85 | J21: 85 | K21: 76
A22: JAVI | B22: DEF/ARQ | C22: lento | D22: 60 | E22: 77 | F22: 69 | G22: 64 | H22: 71 | I22: 80 | J22: 64 | K22: 90
A23: JEAN FRANCO | B23: DEL | C23: lento | D23: 48 | E23: 48 | F23: 64 | G23: 64 | H23: 64 | I23: 81 | J23: 50 | K23: 56
A24: MANU | B24: LAT/MED | C24: rapido | D24: 84 | E24: 90 | F24: 85 | G24: 99 | H24: 85 | I24: 71 | J24: 90
A25: MARCELO | B25: MED/LAT | C25: lento | D25: 58 | E25: 45 | F25: 77 | G25: 50 | H25: 84 | I25: 40 | J25: 56 | K25: 71
A26: MARIAN | B26: DEL/MED | C26: lento | D26: 85 | E26: 45 | F26: 82 | G26: 50 | H26: 76 | I26: 60 | J26: 71 | K26: 80
A27: MATI BRAIAN | B27: DEF/MED | C27: rapido | D27: 76 | E27: 71 | F27: 80 | G27: 90 | H27: 56 | I27: 60 | J27: 71 | K27: 72
A28: MATI ROSALES | B28: MED/LAT | C28: rapido | D28: 80 | E28: 82 | F28: 99 | G28: 76 | H28: 95 | I28: 80 | J28: 85
A29: MAURI | B29: DEL | C29: rapido | D29: 80 | E29: 56 | F29: 71 | G29: 81 | H29: 71 | I29: 80 | J29: 76 | K29: 71
A30: MAXI | B30: MED | C30: lento | D30: 60 | E30: 45 | F30: 76 | G30: 48 | H30: 64 | I30: 60 | J30: 50 | K30: 54
A31: NICO | B31: MED/LAT | C31: rapido | D31: 80 | E31: 56 | F31: 80 | G31: 71 | H31: 80 | I31: 71 | J31: 71 | K31: 71
A32: PABLO | B32: DEF/LAT | C32: rapido | D32: 64 | E32: 92 | F32: 80 | G32: 80 | H32: 80 | I32: 95 | J32: 95
A33: PABLO CASTILLO | B33: LAT/MED | C33: lento | D33: 64 | E33: 80 | F33: 80 | G33: 64 | H33: 85 | I33: 76 | J33: 64 | K33: 71
A34: PABLO GARCIA | B34: MED/LAT | C34: rapido | D34: 51 | E34: 64 | F34: 58 | G34: 71 | H34: 71 | I34: 85 | J34: 80 | K34: 71
A35: PELA | B35: DEL/MED | C35: rapido | D35: 85 | E35: 76 | F35: 85 | G35: 76 | H35: 60 | I35: 85 | J35: 50 | K35: 76
A36: PULY | B36: DEL/MED | C36: lento | D36: 64 | E36: 35 | F36: 92 | G36: 50 | H36: 64 | I36: 50 | J36: 50 | K36: 71
A37: RODRI CHAVEZ | B37: LAT/MED | C37: rapido | D37: 76 | E37: 82 | F37: 80 | G37: 85 | H37: 85 | I37: 90 | J37: 90 | K37: 76
A38: RODRI SUAREZ | B38: DEF/ARQ | C38: lento | D38: 50 | E38: 77 | F38: 60 | G38: 64 | H38: 76 | I38: 80 | J38: 80 | K38: 80
A39: SANTI | B39: ARQ/MED | C39: rapido | D39: 64 | E39: 64 | F39: 92 | G39: 81 | H39: 64 | I39: 64 | J39: 81 | K39: 71
A40: SEBACORTEZ | B40: DEF/ARQ | C40: lento | D40: 71 | E40: 82 | F40: 80 | G40: 60 | H40: 76 | I40: 85 | J40: 64 | K40: 90
...

Sheet Rodri
A1: Nombre jugador | B1: Posiciones | C1: Ritmo base | D1: Ataque | E1: Solidez | F1: Tecnica | G1: Ritmo | H1: Equipo | I1: Mentalidad | J1: Regularidad | K1: Arquero | L1: Comentarios
A2: ALE CUERVO | B2: LAT/MED | C2: lento | D2: 60 | E2: 56 | F2: 71 | G2: 64 | H2: 64 | I2: 50 | J2: 60 | K2: 76
A3: ALEXIS | B3: LAT/MED | C3: rapido | D3: 76 | E3: 76 | F3: 80 | G3: 90 | H3: 71 | I3: 85 | J3: 90 | K3: 71
A4: ANIBAL | B4: DEL | C4: lento | D4: 77 | E4: 45 | F4: 76 | G4: 40 | H4: 45 | I4: 50 | J4: 60 | K4: 85
A5: AUGUSTO | B5: MED/LAT | C5: rapido | D5: 77 | E5: 71 | F5: 85 | G5: 85 | H5: 80 | I5: 60 | J5: 56 | K5: 76
A6: BETO | B6: DEL/MED | C6: lento | D6: 77 | E6: 45 | F6: 76 | G6: 50 | H6: 64 | I6: 76 | J6: 81 | K6: 71
A7: BRIAN | B7: DEL/MED | C7: rapido | D7: 95 | E7: 80 | F7: 95 | G7: 80 | H7: 85 | I7: 60 | J7: 90
A8: CAMILO | B8: MED/DEL | C8: rapido | D8: 80 | E8: 64 | F8: 92 | G8: 85 | H8: 81 | I8: 81 | J8: 81 | K8: 71
A9: CESAR | B9: DEF/LAT | C9: rapido | D9: 76 | E9: 88 | F9: 85 | G9: 71 | H9: 82 | I9: 76 | J9: 90
A10: COMANCHE | B10: LAT/MED | C10: lento | D10: 60 | E10: 58 | F10: 76 | G10: 48 | H10: 45 | I10: 64 | J10: 64 | K10: 80
A11: CRISTIAN | B11: DEL/ARQ | C11: lento | D11: 56 | E11: 40 | F11: 60 | G11: 50 | H11: 60 | I11: 80 | J11: 60 | K11: 76
A12: CUERVO | B12: DEL/DEF | C12: rapido | D12: 99 | E12: 76 | F12: 95 | G12: 76 | H12: 60 | I12: 71 | J12: 60
A13: ELIAN | B13: DEF/DEL | C13: lento | D13: 50 | E13: 40 | F13: 62 | G13: 40 | H13: 60 | I13: 60 | J13: 48 | K13: 71
A14: FACU | B14: DEF/DEL | C14: lento | D14: 56 | E14: 82 | F14: 62 | G14: 60 | H14: 64 | I14: 56 | J14: 80 | K14: 60
A15: FRANCISCO | B15: ARQ/DEL | C15: lento | D15: 40 | E15: 50 | F15: 40 | G15: 64 | H15: 50 | I15: 76 | J15: 60 | K15: 76
A16: FRANCO COMOLLI | B16: MED/DEL | C16: rapido | D16: 85 | E16: 85 | F16: 92 | G16: 90 | H16: 90 | I16: 90 | J16: 95 | K16: 71
A17: FRANCOK | B17: ARQ/LAT | C17: rapido | D17: 40 | E17: 60 | F17: 56 | G17: 76 | H17: 64 | I17: 64 | J17: 71 | K17: 80
A18: FRANQUITO | B18: MED | C18: rapido | D18: 72 | E18: 64 | F18: 80 | G18: 85 | H18: 71 | I18: 71 | J18: 81 | K18: 76
A19: GONZA | B19: ARQ/DEF | C19: lento | D19: 56 | E19: 80 | F19: 64 | G19: 64 | H19: 71 | I19: 71 | J19: 80 | K19: 80
A20: GUILLE | B20: LAT/ARQ | C20: lento | D20: 50 | E20: 40 | F20: 56 | G20: 40 | H20: 60 | I20: 80 | J20: 60 | K20: 71
A21: ISMA | B21: MED/LAT | C21: rapido | D21: 76 | E21: 80 | F21: 90 | G21: 80 | H21: 88 | I21: 85 | J21: 85 | K21: 76
A22: JAVI | B22: DEF/ARQ | C22: lento | D22: 60 | E22: 77 | F22: 69 | G22: 64 | H22: 71 | I22: 80 | J22: 64 | K22: 90
A23: JEAN FRANCO | B23: DEL | C23: lento | D23: 48 | E23: 48 | F23: 64 | G23: 64 | H23: 64 | I23: 81 | J23: 50 | K23: 56
A24: MANU | B24: LAT/MED | C24: rapido | D24: 84 | E24: 90 | F24: 85 | G24: 99 | H24: 85 | I24: 71 | J24: 90
A25: MARCELO | B25: MED/LAT | C25: lento | D25: 58 | E25: 45 | F25: 77 | G25: 50 | H25: 84 | I25: 40 | J25: 56 | K25: 71
A26: MARIAN | B26: DEL/MED | C26: lento | D26: 85 | E26: 45 | F26: 82 | G26: 50 | H26: 76 | I26: 60 | J26: 71 | K26: 80
A27: MATI BRAIAN | B27: DEF/MED | C27: rapido | D27: 76 | E27: 71 | F27: 80 | G27: 90 | H27: 56 | I27: 60 | J27: 71 | K27: 72
A28: MATI ROSALES | B28: MED/LAT | C28: rapido | D28: 80 | E28: 82 | F28: 99 | G28: 76 | H28: 95 | I28: 80 | J28: 85
A29: MAURI | B29: DEL | C29: rapido | D29: 80 | E29: 56 | F29: 71 | G29: 81 | H29: 71 | I29: 80 | J29: 76 | K29: 71
A30: MAXI | B30: MED | C30: lento | D30: 60 | E30: 45 | F30: 76 | G30: 48 | H30: 64 | I30: 60 | J30: 50 | K30: 54
A31: NICO | B31: MED/LAT | C31: rapido | D31: 80 | E31: 56 | F31: 80 | G31: 71 | H31: 80 | I31: 71 | J31: 71 | K31: 71
A32: PABLO | B32: DEF/LAT | C32: rapido | D32: 64 | E32: 92 | F32: 80 | G32: 80 | H32: 80 | I32: 95 | J32: 95
A33: PABLO CASTILLO | B33: LAT/MED | C33: lento | D33: 64 | E33: 80 | F33: 80 | G33: 64 | H33: 85 | I33: 76 | J33: 64 | K33: 71
A34: PABLO GARCIA | B34: MED/LAT | C34: rapido | D34: 51 | E34: 64 | F34: 58 | G34: 71 | H34: 71 | I34: 85 | J34: 80 | K34: 71
A35: PELA | B35: DEL/MED | C35: rapido | D35: 85 | E35: 76 | F35: 85 | G35: 76 | H35: 60 | I35: 85 | J35: 50 | K35: 76
A36: PULY | B36: DEL/MED | C36: lento | D36: 64 | E36: 35 | F36: 92 | G36: 50 | H36: 64 | I36: 50 | J36: 50 | K36: 71
A37: RODRI CHAVEZ | B37: LAT/MED | C37: rapido | D37: 76 | E37: 82 | F37: 80 | G37: 85 | H37: 85 | I37: 90 | J37: 90 | K37: 76
A38: RODRI SUAREZ | B38: DEF/ARQ | C38: lento | D38: 50 | E38: 77 | F38: 60 | G38: 64 | H38: 76 | I38: 80 | J38: 80 | K38: 80
A39: SANTI | B39: ARQ/MED | C39: rapido | D39: 64 | E39: 64 | F39: 92 | G39: 81 | H39: 64 | I39: 64 | J39: 81 | K39: 71
A40: SEBACORTEZ | B40: DEF/ARQ | C40: lento | D40: 71 | E40: 82 | F40: 80 | G40: 60 | H40: 76 | I40: 85 | J40: 64 | K40: 90
...

Sheet Pablo
A1: Nombre jugador | B1: Posiciones | C1: Ritmo base | D1: Ataque | E1: Solidez | F1: Tecnica | G1: Ritmo | H1: Equipo | I1: Mentalidad | J1: Regularidad | K1: Arquero | L1: Comentarios
A2: ALE CUERVO | B2: LAT/MED | C2: lento | D2: 60 | E2: 56 | F2: 71 | G2: 64 | H2: 64 | I2: 50 | J2: 60 | K2: 76
A3: ALEXIS | B3: LAT/MED | C3: rapido | D3: 76 | E3: 76 | F3: 80 | G3: 90 | H3: 71 | I3: 85 | J3: 90 | K3: 71
A4: ANIBAL | B4: DEL | C4: lento | D4: 77 | E4: 45 | F4: 76 | G4: 40 | H4: 45 | I4: 50 | J4: 60 | K4: 85
A5: AUGUSTO | B5: MED/LAT | C5: rapido | D5: 77 | E5: 71 | F5: 85 | G5: 85 | H5: 80 | I5: 60 | J5: 56 | K5: 76
A6: BETO | B6: DEL/MED | C6: lento | D6: 77 | E6: 45 | F6: 76 | G6: 50 | H6: 64 | I6: 76 | J6: 81 | K6: 71
A7: BRIAN | B7: DEL/MED | C7: rapido | D7: 95 | E7: 80 | F7: 95 | G7: 80 | H7: 85 | I7: 60 | J7: 90
A8: CAMILO | B8: MED/DEL | C8: rapido | D8: 80 | E8: 64 | F8: 92 | G8: 85 | H8: 81 | I8: 81 | J8: 81 | K8: 71
A9: CESAR | B9: DEF/LAT | C9: rapido | D9: 76 | E9: 88 | F9: 85 | G9: 71 | H9: 82 | I9: 76 | J9: 90
A10: COMANCHE | B10: LAT/MED | C10: lento | D10: 60 | E10: 58 | F10: 76 | G10: 48 | H10: 45 | I10: 64 | J10: 64 | K10: 80
A11: CRISTIAN | B11: DEL/ARQ | C11: lento | D11: 56 | E11: 40 | F11: 60 | G11: 50 | H11: 60 | I11: 80 | J11: 60 | K11: 76
A12: CUERVO | B12: DEL/DEF | C12: rapido | D12: 99 | E12: 76 | F12: 95 | G12: 76 | H12: 60 | I12: 71 | J12: 60
A13: ELIAN | B13: DEF/DEL | C13: lento | D13: 50 | E13: 40 | F13: 62 | G13: 40 | H13: 60 | I13: 60 | J13: 48 | K13: 71
A14: FACU | B14: DEF/DEL | C14: lento | D14: 56 | E14: 82 | F14: 62 | G14: 60 | H14: 64 | I14: 56 | J14: 80 | K14: 60
A15: FRANCISCO | B15: ARQ/DEL | C15: lento | D15: 40 | E15: 50 | F15: 40 | G15: 64 | H15: 50 | I15: 76 | J15: 60 | K15: 76
A16: FRANCO COMOLLI | B16: MED/DEL | C16: rapido | D16: 85 | E16: 85 | F16: 92 | G16: 90 | H16: 90 | I16: 90 | J16: 95 | K16: 71
A17: FRANCOK | B17: ARQ/LAT | C17: rapido | D17: 40 | E17: 60 | F17: 56 | G17: 76 | H17: 64 | I17: 64 | J17: 71 | K17: 80
A18: FRANQUITO | B18: MED | C18: rapido | D18: 72 | E18: 64 | F18: 80 | G18: 85 | H18: 71 | I18: 71 | J18: 81 | K18: 76
A19: GONZA | B19: ARQ/DEF | C19: lento | D19: 56 | E19: 80 | F19: 64 | G19: 64 | H19: 71 | I19: 71 | J19: 80 | K19: 80
A20: GUILLE | B20: LAT/ARQ | C20: lento | D20: 50 | E20: 40 | F20: 56 | G20: 40 | H20: 60 | I20: 80 | J20: 60 | K20: 71
A21: ISMA | B21: MED/LAT | C21: rapido | D21: 76 | E21: 80 | F21: 90 | G21: 80 | H21: 88 | I21: 85 | J21: 85 | K21: 76
A22: JAVI | B22: DEF/ARQ | C22: lento | D22: 60 | E22: 77 | F22: 69 | G22: 64 | H22: 71 | I22: 80 | J22: 64 | K22: 90
A23: JEAN FRANCO | B23: DEL | C23: lento | D23: 48 | E23: 48 | F23: 64 | G23: 64 | H23: 64 | I23: 81 | J23: 50 | K23: 56
A24: MANU | B24: LAT/MED | C24: rapido | D24: 84 | E24: 90 | F24: 85 | G24: 99 | H24: 85 | I24: 71 | J24: 90
A25: MARCELO | B25: MED/LAT | C25: lento | D25: 58 | E25: 45 | F25: 77 | G25: 50 | H25: 84 | I25: 40 | J25: 56 | K25: 71
A26: MARIAN | B26: DEL/MED | C26: lento | D26: 85 | E26: 45 | F26: 82 | G26: 50 | H26: 76 | I26: 60 | J26: 71 | K26: 80
A27: MATI BRAIAN | B27: DEF/MED | C27: rapido | D27: 76 | E27: 71 | F27: 80 | G27: 90 | H27: 56 | I27: 60 | J27: 71 | K27: 72
A28: MATI ROSALES | B28: MED/LAT | C28: rapido | D28: 80 | E28: 82 | F28: 99 | G28: 76 | H28: 95 | I28: 80 | J28: 85
A29: MAURI | B29: DEL | C29: rapido | D29: 80 | E29: 56 | F29: 71 | G29: 81 | H29: 71 | I29: 80 | J29: 76 | K29: 71
A30: MAXI | B30: MED | C30: lento | D30: 60 | E30: 45 | F30: 76 | G30: 48 | H30: 64 | I30: 60 | J30: 50 | K30: 54
A31: NICO | B31: MED/LAT | C31: rapido | D31: 80 | E31: 56 | F31: 80 | G31: 71 | H31: 80 | I31: 71 | J31: 71 | K31: 71
A32: PABLO | B32: DEF/LAT | C32: rapido | D32: 64 | E32: 92 | F32: 80 | G32: 80 | H32: 80 | I32: 95 | J32: 95
A33: PABLO CASTILLO | B33: LAT/MED | C33: lento | D33: 64 | E33: 80 | F33: 80 | G33: 64 | H33: 85 | I33: 76 | J33: 64 | K33: 71
A34: PABLO GARCIA | B34: MED/LAT | C34: rapido | D34: 51 | E34: 64 | F34: 58 | G34: 71 | H34: 71 | I34: 85 | J34: 80 | K34: 71
A35: PELA | B35: DEL/MED | C35: rapido | D35: 85 | E35: 76 | F35: 85 | G35: 76 | H35: 60 | I35: 85 | J35: 50 | K35: 76
A36: PULY | B36: DEL/MED | C36: lento | D36: 64 | E36: 35 | F36: 92 | G36: 50 | H36: 64 | I36: 50 | J36: 50 | K36: 71
A37: RODRI CHAVEZ | B37: LAT/MED | C37: rapido | D37: 76 | E37: 82 | F37: 80 | G37: 85 | H37: 85 | I37: 90 | J37: 90 | K37: 76
A38: RODRI SUAREZ | B38: DEF/ARQ | C38: lento | D38: 50 | E38: 77 | F38: 60 | G38: 64 | H38: 76 | I38: 80 | J38: 80 | K38: 80
A39: SANTI | B39: ARQ/MED | C39: rapido | D39: 64 | E39: 64 | F39: 92 | G39: 81 | H39: 64 | I39: 64 | J39: 81 | K39: 71
A40: SEBACORTEZ | B40: DEF/ARQ | C40: lento | D40: 71 | E40: 82 | F40: 80 | G40: 60 | H40: 76 | I40: 85 | J40: 64 | K40: 90
...

Sheet Instrucciones
A1: Planilla de carga de stats - Goodfellas
A2: Escala de carga: 0 a 99.
A3: Subir este archivo a Google Drive y abrirlo con Google Sheets. Compartir el MISMO archivo con los directivos con permiso de editor.
A4: Cada directivo debe completar solamente su pesta?a: Marcelo, Braian, Cesar, Marian, Guille, Pela, Rodri o Pablo.
A5: La pesta?a Consolidado promedia automaticamente los valores numericos de todos los directivos.
A6: Columnas: Ataque, Solidez, Tecnica, Ritmo, Equipo, Mentalidad, Regularidad, Arquero.
A7: Comentarios es libre para dudas o ajustes puntuales.
